Workbook

Sheet BWT
A1: MODELO | B1: ANO | C1: PLACA | D1: ROTA | E1: MOTORISTA | F1: KM CARREGADO | G1: KM VAZIO | H1: HODÔMETRO | I1: FATURAMENTO | J1: VOLUME TRANSPORTADO | K1: CUSTO FIXO (SEM DEPREC.) | L1: CUSTO VARIÁVEL | M1: EBITDA ESTIMADO | N1: EBITDA ATINGIDO | O1: RESULTADO | P1: MARGEM | Q1: FATURAMENTO POR KM | R1: MÉDIA KM/L | S1: LITROS CONSUMIDOS | T1: Coluna1 | U1: 6 | V1: EBITDA BWT | W1: =Tabela1[[#Totals],[RESULTADO]] -> 202319.24 | Z1: Dia | AA1: =DAY(TODAY()) -> 13 | AB1: CUSTO FIXO 7 EIXOS | AC1: DEPREC. 7 EIXOS | AD1: CUSTO FIXO 7 EIXOS SEM DEPREC. | AF1: CUSTO FIXO 9 EIXOS | AG1: DEPREC. 9 EIXOS | AH1: CUSTO FIXO 9 EIXOS SEM DEPREC.
A2: VOLVO/FH 540 6X4T | B2: 2020 | C2: BDQ4E21 | D2: ISOTANK | E2: =IFERROR(_xlfn.XLOOKUP(Tabela1[[#This Row],[PLACA]],'Telemetria Sighra'!F:F,'Telemetria Sighra'!T:T),"NÃO EMBARCADO") -> MARCELO DE JESUS ARAUJO - 118 | F2: {=SUMPRODUCT((ISNUMBER(FIND(C2,Faturamento!$F$2:$F$1014)))*(Faturamento!$AA$2:$AA$1014))} -> 0 | G2: =Tabela1[[#This Row],[HODÔMETRO]]-Tabela1[[#This Row],[KM CARREGADO]] -> 5156.51 | H2: =_xlfn.XLOOKUP(C2,'Telemetria Sighra'!F:F,'Telemetria Sighra'!R:R,0) -> 5156.51 | I2: =SUMIF(Faturamento!AC:AC,C2,Faturamento!T:T) -> 0 | J2: {=SUMPRODUCT((ISNUMBER(FIND(C2,Faturamento!$F$2:$F$1014)))*(Faturamento!$R$2:$R$1014))} -> 0 | K2: =$AH$2/30*$AA$1 -> 9479.7957 | L2: 4.4694 | M2: 40000 | N2: =Tabela1[[#This Row],[RESULTADO]]/Tabela1[[#This Row],[EBITDA ESTIMADO]] -> -0.81315754 | O2: =Tabela1[[#This Row],[FATURAMENTO]]-Tabela1[[#This Row],[CUSTO FIXO (SEM DEPREC.)]]-(Tabela1[[#This Row],[CUSTO VARIÁVEL]]*Tabela1[[#This Row],[HODÔMETRO]])+IF(COUNTIFS('ROTAS REALIZADAS'!A:A,Tabela1[[#This Row],[PLACA]],'ROTAS REALIZADAS'!A:A,"SANTOS/PAULINIA")>0,$AA$1*1233.33,0) -> -32526.302 | P2: =IFERROR(Tabela1[[#This Row],[RESULTADO]]/Tabela1[[#This Row],[FATURAMENTO]],"-") -> - | Q2: =IFERROR(I2/H2,"-") -> 0 | R2: =_xlfn.XLOOKUP(C2,'Telemetria Sighra'!F:F,'Telemetria Sighra'!S:S,0) -> 1.8454744 | S2: =_xlfn.XLOOKUP(Tabela1[[#This Row],[PLACA]],'Telemetria Sighra'!F:F,'Telemetria Sighra'!I:I,0) -> 2794.23 | T2: =IFERROR((Tabela1[[#This Row],[LITROS CONSUMIDOS]]*$U$1)/Tabela1[[#This Row],[HODÔMETRO]],"-") -> 3.2513037 | V2: EBITDA SUBCONTRATADO | W2: =SUMIF(Faturamento!AB:AB,"SUBCONTRATADO",Faturamento!T:T)*0.3 -> 38271.891 | AB2: 37311.23 | AC2: =230183.45/12 -> 19181.954 | AD2: =AB2-AC2 -> 18129.276 | AF2: 45740.36 | AG2: =286366.9/12 -> 23863.908 | AH2: =AF2-AG2 -> 21876.452
A3: DAF/XF FTT 530 | B3: 2021 | C3: RHG5D76 | D3: SANTOS X PAULINIA | E3: =IFERROR(_xlfn.XLOOKUP(Tabela1[[#This Row],[PLACA]],'Telemetria Sighra'!F:F,'Telemetria Sighra'!T:T),"NÃO EMBARCADO") -> JEFFERSON APARECIDO DE LIMA - 10857 | F3: {=SUMPRODUCT((ISNUMBER(FIND(C3,Faturamento!$F$2:$F$1014)))*(Faturamento!$AA$2:$AA$1014))} -> 0 | G3: =Tabela1[[#This Row],[HODÔMETRO]]-Tabela1[[#This Row],[KM CARREGADO]] -> 1342.87 | H3: =_xlfn.XLOOKUP(C3,'Telemetria Sighra'!F:F,'Telemetria Sighra'!R:R,0) -> 1342.87 | I3: =SUMIF(Faturamento!AC:AC,C3,Faturamento!T:T) -> 0 | J3: {=SUMPRODUCT((ISNUMBER(FIND(C3,Faturamento!$F$2:$F$1014)))*(Faturamento!$R$2:$R$1014))} -> 0 | K3: =$AH$2/30*$AA$1 -> 9479.7957 | L3: 4.4694 | M3: 39990 | N3: =Tabela1[[#This Row],[RESULTADO]]/Tabela1[[#This Row],[EBITDA ESTIMADO]] -> -0.38713726 | O3: =Tabela1[[#This Row],[FATURAMENTO]]-Tabela1[[#This Row],[CUSTO FIXO (SEM DEPREC.)]]-(Tabela1[[#This Row],[CUSTO VARIÁVEL]]*Tabela1[[#This Row],[HODÔMETRO]])+IF(COUNTIFS('ROTAS REALIZADAS'!A:A,Tabela1[[#This Row],[PLACA]],'ROTAS REALIZADAS'!A:A,"SANTOS/PAULINIA")>0,$AA$1*1233.33,0) -> -15481.619 | P3: =IFERROR(Tabela1[[#This Row],[RESULTADO]]/Tabela1[[#This Row],[FATURAMENTO]],"-") -> - | Q3: =IFERROR(I3/H3,"-") -> 0 | R3: =_xlfn.XLOOKUP(C3,'Telemetria Sighra'!F:F,'Telemetria Sighra'!S:S,0) -> 1.7216831 | S3: =_xlfn.XLOOKUP(Tabela1[[#This Row],[PLACA]],'Telemetria Sighra'!F:F,'Telemetria Sighra'!I:I,0) -> 780.01 | T3: =IFERROR((Tabela1[[#This Row],[LITROS CONSUMIDOS]]*$U$1)/Tabela1[[#This Row],[HODÔMETRO]],"-") -> 3.4851177 | V3: RESULTADO | W3: =W1+W2 -> 240591.13
A4: DAF/XF FTT 530 | B4: 2024 | C4: SEX2C71 | D4: SANTOS X PAULINIA | E4: =IFERROR(_xlfn.XLOOKUP(Tabela1[[#This Row],[PLACA]],'Telemetria Sighra'!F:F,'Telemetria Sighra'!T:T),"NÃO EMBARCADO") -> ORVITO ANDERLE - 217 | F4: {=SUMPRODUCT((ISNUMBER(FIND(C4,Faturamento!$F$2:$F$1014)))*(Faturamento!$AA$2:$AA$1014))} -> 0 | G4: =Tabela1[[#This Row],[HODÔMETRO]]-Tabela1[[#This Row],[KM CARREGADO]] -> 1018.19 | H4: =_xlfn.XLOOKUP(C4,'Telemetria Sighra'!F:F,'Telemetria Sighra'!R:R,0) -> 1018.19 | I4: =SUMIF(Faturamento!AC:AC,C4,Faturamento!T:T) -> 0 | J4: {=SUMPRODUCT((ISNUMBER(FIND(C4,Faturamento!$F$2:$F$1014)))*(Faturamento!$R$2:$R$1014))} -> 0 | K4: =$AH$2/30*$AA$1 -> 9479.7957 | L4: 4.4694 | M4: 39990 | N4: =Tabela1[[#This Row],[RESULTADO]]/Tabela1[[#This Row],[EBITDA ESTIMADO]] -> -0.35085007 | O4: =Tabela1[[#This Row],[FATURAMENTO]]-Tabela1[[#This Row],[CUSTO FIXO (SEM DEPREC.)]]-(Tabela1[[#This Row],[CUSTO VARIÁVEL]]*Tabela1[[#This Row],[HODÔMETRO]])+IF(COUNTIFS('ROTAS REALIZADAS'!A:A,Tabela1[[#This Row],[PLACA]],'ROTAS REALIZADAS'!A:A,"SANTOS/PAULINIA")>0,$AA$1*1233.33,0) -> -14030.494 | P4: =IFERROR(Tabela1[[#This Row],[RESULTADO]]/Tabela1[[#This Row],[FATURAMENTO]],"-") -> - | Q4: =IFERROR(I4/H4,"-") -> 0 | R4: =_xlfn.XLOOKUP(C4,'Telemetria Sighra'!F:F,'Telemetria Sighra'!S:S,0) -> 1.592123 | S4: =_xlfn.XLOOKUP(Tabela1[[#This Row],[PLACA]],'Telemetria Sighra'!F:F,'Telemetria Sighra'!I:I,0) -> 639.58 | T4: =IFERROR((Tabela1[[#This Row],[LITROS CONSUMIDOS]]*$U$1)/Tabela1[[#This Row],[HODÔMETRO]],"-") -> 3.7689233
A5: DAF/XF FTT 530 | B5: 2024 | C5: SFA7F70 | D5: VIBRA | E5: =IFERROR(_xlfn.XLOOKUP(Tabela1[[#This Row],[PLACA]],'Telemetria Sighra'!F:F,'Telemetria Sighra'!T:T),"NÃO EMBARCADO") -> PAULO ROBERTO EVANGELISTA SOARES - 255 | F5: {=SUMPRODUCT((ISNUMBER(FIND(C5,Faturamento!$F$2:$F$1014)))*(Faturamento!$AA$2:$AA$1014))} -> 430 | G5: =Tabela1[[#This Row],[HODÔMETRO]]-Tabela1[[#This Row],[KM CARREGADO]] -> 1702.44 | H5: =_xlfn.XLOOKUP(C5,'Telemetria Sighra'!F:F,'Telemetria Sighra'!R:R,0) -> 2132.44 | I5: =SUMIF(Faturamento!AC:AC,C5,Faturamento!T:T) -> 6300.07 | J5: {=SUMPRODUCT((ISNUMBER(FIND(C5,Faturamento!$F$2:$F$1014)))*(Faturamento!$R$2:$R$1014))} -> 124316 | K5: =$AH$2/30*$AA$1 -> 9479.7957 | L5: 4.4694 | M5: 69761 | N5: =Tabela1[[#This Row],[RESULTADO]]/Tabela1[[#This Row],[EBITDA ESTIMADO]] -> -0.18219998 | O5: =Tabela1[[#This Row],[FATURAMENTO]]-Tabela1[[#This Row],[CUSTO FIXO (SEM DEPREC.)]]-(Tabela1[[#This Row],[CUSTO VARIÁVEL]]*Tabela1[[#This Row],[HODÔMETRO]])+IF(COUNTIFS('ROTAS REALIZADAS'!A:A,Tabela1[[#This Row],[PLACA]],'ROTAS REALIZADAS'!A:A,"SANTOS/PAULINIA")>0,$AA$1*1233.33,0) -> -12710.453 | P5: =IFERROR(Tabela1[[#This Row],[RESULTADO]]/Tabela1[[#This Row],[FATURAMENTO]],"-") -> -2.0175098 | Q5: =IFERROR(I5/H5,"-") -> 2.954395 | R5: =_xlfn.XLOOKUP(C5,'Telemetria Sighra'!F:F,'Telemetria Sighra'!S:S,0) -> 2.1289231 | S5: =_xlfn.XLOOKUP(Tabela1[[#This Row],[PLACA]],'Telemetria Sighra'!F:F,'Telemetria Sighra'!I:I,0) -> 1001.76 | T5: =IFERROR((Tabela1[[#This Row],[LITROS CONSUMIDOS]]*$U$1)/Tabela1[[#This Row],[HODÔMETRO]],"-") -> 2.8186303
A6: SCANIA/R 480 A6X4 | B6: 2016 | C6: BAY4H67 | D6: PGUA X LAPA | E6: =IFERROR(_xlfn.XLOOKUP(Tabela1[[#This Row],[PLACA]],'Telemetria Sighra'!F:F,'Telemetria Sighra'!T:T),"NÃO EMBARCADO") -> LUIZ TOME DOS SANTOS FILHO - 10844 | F6: {=SUMPRODUCT((ISNUMBER(FIND(C6,Faturamento!$F$2:$F$1014)))*(Faturamento!$AA$2:$AA$1014))} -> 0 | G6: =Tabela1[[#This Row],[HODÔMETRO]]-Tabela1[[#This Row],[KM CARREGADO]] -> 1108.95 | H6: =_xlfn.XLOOKUP(C6,'Telemetria Sighra'!F:F,'Telemetria Sighra'!R:R,0) -> 1108.95 | I6: =SUMIF(Faturamento!AC:AC,C6,Faturamento!T:T) -> 0 | J6: {=SUMPRODUCT((ISNUMBER(FIND(C6,Faturamento!$F$2:$F$1014)))*(Faturamento!$R$2:$R$1014))} -> 0 | K6: =$AD$2/30*$AA$1 -> 7856.0195 | L6: 3.55 | M6: 36051 | N6: =Tabela1[[#This Row],[RESULTADO]]/Tabela1[[#This Row],[EBITDA ESTIMADO]] -> -0.32711414 | O6: =Tabela1[[#This Row],[FATURAMENTO]]-Tabela1[[#This Row],[CUSTO FIXO (SEM DEPREC.)]]-(Tabela1[[#This Row],[CUSTO VARIÁVEL]]*Tabela1[[#This Row],[HODÔMETRO]])+IF(COUNTIFS('ROTAS REALIZADAS'!A:A,Tabela1[[#This Row],[PLACA]],'ROTAS REALIZADAS'!A:A,"SANTOS/PAULINIA")>0,$AA$1*1233.33,0) -> -11792.792 | P6: =IFERROR(Tabela1[[#This Row],[RESULTADO]]/Tabela1[[#This Row],[FATURAMENTO]],"-") -> - | Q6: =IFERROR(I6/H6,"-") -> 0 | R6: =_xlfn.XLOOKUP(C6,'Telemetria Sighra'!F:F,'Telemetria Sighra'!S:S,0) -> 2.1881301 | S6: =_xlfn.XLOOKUP(Tabela1[[#This Row],[PLACA]],'Telemetria Sighra'!F:F,'Telemetria Sighra'!I:I,0) -> 506.83 | T6: =IFERROR((Tabela1[[#This Row],[LITROS CONSUMIDOS]]*$U$1)/Tabela1[[#This Row],[HODÔMETRO]],"-") -> 2.7422156
A7: SCANIA/R 480 A6X4 | B7: 2016 | C7: BAQ0D27 | D7: METANOL | E7: =IFERROR(_xlfn.XLOOKUP(Tabela1[[#This Row],[PLACA]],'Telemetria Sighra'!F:F,'Telemetria Sighra'!T:T),"NÃO EMBARCADO") -> CLODOALDO SANTIAGO - 10247 | F7: {=SUMPRODUCT((ISNUMBER(FIND(C7,Faturamento!$F$2:$F$1014)))*(Faturamento!$AA$2:$AA$1014))} -> 0 | G7: =Tabela1[[#This Row],[HODÔMETRO]]-Tabela1[[#This Row],[KM CARREGADO]] -> 553.76 | H7: =_xlfn.XLOOKUP(C7,'Telemetria Sighra'!F:F,'Telemetria Sighra'!R:R,0) -> 553.76 | I7: =SUMIF(Faturamento!AC:AC,C7,Faturamento!T:T) -> 0 | J7: {=SUMPRODUCT((ISNUMBER(FIND(C7,Faturamento!$F$2:$F$1014)))*(Faturamento!$R$2:$R$1014))} -> 0 | K7: =$AD$2/30*$AA$1 -> 7856.0195 | L7: 3.55 | M7: 47896 | N7: =Tabela1[[#This Row],[RESULTADO]]/Tabela1[[#This Row],[EBITDA ESTIMADO]] -> -0.20506655 | O7: =Tabela1[[#This Row],[FATURAMENTO]]-Tabela1[[#This Row],[CUSTO FIXO (SEM DEPREC.)]]-(Tabela1[[#This Row],[CUSTO VARIÁVEL]]*Tabela1[[#This Row],[HODÔMETRO]])+IF(COUNTIFS('ROTAS REALIZADAS'!A:A,Tabela1[[#This Row],[PLACA]],'ROTAS REALIZADAS'!A:A,"SANTOS/PAULINIA")>0,$AA$1*1233.33,0) -> -9821.8675 | P7: =IFERROR(Tabela1[[#This Row],[RESULTADO]]/Tabela1[[#This Row],[FATURAMENTO]],"-") -> - | Q7: =IFERROR(I7/H7,"-") -> 0 | R7: =_xlfn.XLOOKUP(C7,'Telemetria Sighra'!F:F,'Telemetria Sighra'!S:S,0) -> 2.6425231 | S7: =_xlfn.XLOOKUP(Tabela1[[#This Row],[PLACA]],'Telemetria Sighra'!F:F,'Telemetria Sighra'!I:I,0) -> 209.58 | T7: =IFERROR((Tabela1[[#This Row],[LITROS CONSUMIDOS]]*$U$1)/Tabela1[[#This Row],[HODÔMETRO]],"-") -> 2.2708032
A8: DAF/XF FTT 530 | B8: 2023 | C8: SEE2J88 | D8: SANTOS X PAULINIA | E8: =IFERROR(_xlfn.XLOOKUP(Tabela1[[#This Row],[PLACA]],'Telemetria Sighra'!F:F,'Telemetria Sighra'!T:T),"NÃO EMBARCADO") -> MARCOS AURELIO NOGUEIRA - 235 | F8: {=SUMPRODUCT((ISNUMBER(FIND(C8,Faturamento!$F$2:$F$1014)))*(Faturamento!$AA$2:$AA$1014))} -> 494 | G8: =Tabela1[[#This Row],[HODÔMETRO]]-Tabela1[[#This Row],[KM CARREGADO]] -> 1448.6 | H8: =_xlfn.XLOOKUP(C8,'Telemetria Sighra'!F:F,'Telemetria Sighra'!R:R,0) -> 1942.6 | I8: =SUMIF(Faturamento!AC:AC,C8,Faturamento!T:T) -> 8477.29 | J8: {=SUMPRODUCT((ISNUMBER(FIND(C8,Faturamento!$F$2:$F$1014)))*(Faturamento!$R$2:$R$1014))} -> 121889 | K8: =$AH$2/30*$AA$1 -> 9479.7957 | L8: 4.4694 | M8: 39990 | N8: =Tabela1[[#This Row],[RESULTADO]]/Tabela1[[#This Row],[EBITDA ESTIMADO]] -> -0.2421796 | O8: =Tabela1[[#This Row],[FATURAMENTO]]-Tabela1[[#This Row],[CUSTO FIXO (SEM DEPREC.)]]-(Tabela1[[#This Row],[CUSTO VARIÁVEL]]*Tabela1[[#This Row],[HODÔMETRO]])+IF(COUNTIFS('ROTAS REALIZADAS'!A:A,Tabela1[[#This Row],[PLACA]],'ROTAS REALIZADAS'!A:A,"SANTOS/PAULINIA")>0,$AA$1*1233.33,0) -> -9684.7622 | P8: =IFERROR(Tabela1[[#This Row],[RESULTADO]]/Tabela1[[#This Row],[FATURAMENTO]],"-") -> -1.1424361 | Q8: =IFERROR(I8/H8,"-") -> 4.3638886 | R8: =_xlfn.XLOOKUP(C8,'Telemetria Sighra'!F:F,'Telemetria Sighra'!S:S,0) -> 1.5095532 | S8: =_xlfn.XLOOKUP(Tabela1[[#This Row],[PLACA]],'Telemetria Sighra'!F:F,'Telemetria Sighra'!I:I,0) -> 1287.01 | T8: =IFERROR((Tabela1[[#This Row],[LITROS CONSUMIDOS]]*$U$1)/Tabela1[[#This Row],[HODÔMETRO]],"-") -> 3.9751158
A9: VOLVO/FH 500 6X4T S BIO | B9: 2025 | C9: TAW2A67 | D9: VIBRA | E9: =IFERROR(_xlfn.XLOOKUP(Tabela1[[#This Row],[PLACA]],'Telemetria Sighra'!F:F,'Telemetria Sighra'!T:T),"NÃO EMBARCADO") -> LUIZ ALEX DOS SANTOS - 167 | F9: {=SUMPRODUCT((ISNUMBER(FIND(C9,Faturamento!$F$2:$F$1014)))*(Faturamento!$AA$2:$AA$1014))} -> 20 | G9: =Tabela1[[#This Row],[HODÔMETRO]]-Tabela1[[#This Row],[KM CARREGADO]] -> 351.2 | H9: =_xlfn.XLOOKUP(C9,'Telemetria Sighra'!F:F,'Telemetria Sighra'!R:R,0) -> 371.2 | I9: =SUMIF(Faturamento!AC:AC,C9,Faturamento!T:T) -> 1618.07 | J9: {=SUMPRODUCT((ISNUMBER(FIND(C9,Faturamento!$F$2:$F$1014)))*(Faturamento!$R$2:$R$1014))} -> 60062 | K9: =$AH$2/30*$AA$1 -> 9479.7957 | L9: 4.4694 | M9: 69761 | N9: =Tabela1[[#This Row],[RESULTADO]]/Tabela1[[#This Row],[EBITDA ESTIMADO]] -> -0.13647693 | O9: =Tabela1[[#This Row],[FATURAMENTO]]-Tabela1[[#This Row],[CUSTO FIXO (SEM DEPREC.)]]-(Tabela1[[#This Row],[CUSTO VARIÁVEL]]*Tabela1[[#This Row],[HODÔMETRO]])+IF(COUNTIFS('ROTAS REALIZADAS'!A:A,Tabela1[[#This Row],[PLACA]],'ROTAS REALIZADAS'!A:A,"SANTOS/PAULINIA")>0,$AA$1*1233.33,0) -> -9520.767 | P9: =IFERROR(Tabela1[[#This Row],[RESULTADO]]/Tabela1[[#This Row],[FATURAMENTO]],"-") -> -5.8840267 | Q9: =IFERROR(I9/H9,"-") -> 4.3590248 | R9: =_xlfn.XLOOKUP(C9,'Telemetria Sighra'!F:F,'Telemetria Sighra'!S:S,0) -> 2.0648462 | S9: =_xlfn.XLOOKUP(Tabela1[[#This Row],[PLACA]],'Telemetria Sighra'!F:F,'Telemetria Sighra'!I:I,0) -> 179.81 | T9: =IFERROR((Tabela1[[#This Row],[LITROS CONSUMIDOS]]*$U$1)/Tabela1[[#This Row],[HODÔMETRO]],"-") -> 2.9064116
A10: DAF/XF FTT 530 | B10: 2021 | C10: RHI3D91 | D10: ISOTANK | E10: =IFERROR(_xlfn.XLOOKUP(Tabela1[[#This Row],[PLACA]],'Telemetria Sighra'!F:F,'Telemetria Sighra'!T:T),"NÃO EMBARCADO") -> NÃO EMBARCADO | F10: {=SUMPRODUCT((ISNUMBER(FIND(C10,Faturamento!$F$2:$F$1014)))*(Faturamento!$AA$2:$AA$1014))} -> 0 | G10: =Tabela1[[#This Row],[HODÔMETRO]]-Tabela1[[#This Row],[KM CARREGADO]] -> 0 | H10: =_xlfn.XLOOKUP(C10,'Telemetria Sighra'!F:F,'Telemetria Sighra'!R:R,0) -> 0 | I10: =SUMIF(Faturamento!AC:AC,C10,Faturamento!T:T) -> 0 | J10: {=SUMPRODUCT((ISNUMBER(FIND(C10,Faturamento!$F$2:$F$1014)))*(Faturamento!$R$2:$R$1014))} -> 0 | K10: =$AH$2/30*$AA$1 -> 9479.7957 | L10: 4.4694 | M10: 40000 | N10: =Tabela1[[#This Row],[RESULTADO]]/Tabela1[[#This Row],[EBITDA ESTIMADO]] -> -0.23699489 | O10: =Tabela1[[#This Row],[FATURAMENTO]]-Tabela1[[#This Row],[CUSTO FIXO (SEM DEPREC.)]]-(Tabela1[[#This Row],[CUSTO VARIÁVEL]]*Tabela1[[#This Row],[HODÔMETRO]])+IF(COUNTIFS('ROTAS REALIZADAS'!A:A,Tabela1[[#This Row],[PLACA]],'ROTAS REALIZADAS'!A:A,"SANTOS/PAULINIA")>0,$AA$1*1233.33,0) -> -9479.7957 | P10: =IFERROR(Tabela1[[#This Row],[RESULTADO]]/Tabela1[[#This Row],[FATURAMENTO]],"-") -> - | Q10: =IFERROR(I10/H10,"-") -> - | R10: =_xlfn.XLOOKUP(C10,'Telemetria Sighra'!F:F,'Telemetria Sighra'!S:S,0) -> 0 | S10: =_xlfn.XLOOKUP(Tabela1[[#This Row],[PLACA]],'Telemetria Sighra'!F:F,'Telemetria Sighra'!I:I,0) -> 0 | T10: =IFERROR((Tabela1[[#This Row],[LITROS CONSUMIDOS]]*$U$1)/Tabela1[[#This Row],[HODÔMETRO]],"-") -> -
A11: VOLVO/FH 540 6X4T | B11: 2020 | C11: BDQ4E34 | D11: Spot melhor tarifa | E11: =IFERROR(_xlfn.XLOOKUP(Tabela1[[#This Row],[PLACA]],'Telemetria Sighra'!F:F,'Telemetria Sighra'!T:T),"NÃO EMBARCADO") -> NÃO EMBARCADO | F11: {=SUMPRODUCT((ISNUMBER(FIND(C11,Faturamento!$F$2:$F$1014)))*(Faturamento!$AA$2:$AA$1014))} -> 0 | G11: =Tabela1[[#This Row],[HODÔMETRO]]-Tabela1[[#This Row],[KM CARREGADO]] -> 0 | H11: =_xlfn.XLOOKUP(C11,'Telemetria Sighra'!F:F,'Telemetria Sighra'!R:R,0) -> 0 | I11: =SUMIF(Faturamento!AC:AC,C11,Faturamento!T:T) -> 0 | J11: {=SUMPRODUCT((ISNUMBER(FIND(C11,Faturamento!$F$2:$F$1014)))*(Faturamento!$R$2:$R$1014))} -> 0 | K11: =$AH$2/30*$AA$1 -> 9479.7957 | L11: 4.4694 | M11: 40000 | N11: =Tabela1[[#This Row],[RESULTADO]]/Tabela1[[#This Row],[EBITDA ESTIMADO]] -> -0.23699489 | O11: =Tabela1[[#This Row],[FATURAMENTO]]-Tabela1[[#This Row],[CUSTO FIXO (SEM DEPREC.)]]-(Tabela1[[#This Row],[CUSTO VARIÁVEL]]*Tabela1[[#This Row],[HODÔMETRO]])+IF(COUNTIFS('ROTAS REALIZADAS'!A:A,Tabela1[[#This Row],[PLACA]],'ROTAS REALIZADAS'!A:A,"SANTOS/PAULINIA")>0,$AA$1*1233.33,0) -> -9479.7957 | P11: =IFERROR(Tabela1[[#This Row],[RESULTADO]]/Tabela1[[#This Row],[FATURAMENTO]],"-") -> - | Q11: =IFERROR(I11/H11,"-") -> - | R11: =_xlfn.XLOOKUP(C11,'Telemetria Sighra'!F:F,'Telemetria Sighra'!S:S,0) -> 0 | S11: =_xlfn.XLOOKUP(Tabela1[[#This Row],[PLACA]],'Telemetria Sighra'!F:F,'Telemetria Sighra'!I:I,0) -> 0 | T11: =IFERROR((Tabela1[[#This Row],[LITROS CONSUMIDOS]]*$U$1)/Tabela1[[#This Row],[HODÔMETRO]],"-") -> -
A12: DAF/XF FTT 530 | B12: 2024 | C12: SFC5F45 | D12: ISOTANK | E12: =IFERROR(_xlfn.XLOOKUP(Tabela1[[#This Row],[PLACA]],'Telemetria Sighra'!F:F,'Telemetria Sighra'!T:T),"NÃO EMBARCADO") -> EMERSON MENON CUNHA - 128 | F12: {=SUMPRODUCT((ISNUMBER(FIND(C12,Faturamento!$F$2:$F$1014)))*(Faturamento!$AA$2:$AA$1014))} -> 645 | G12: =Tabela1[[#This Row],[HODÔMETRO]]-Tabela1[[#This Row],[KM CARREGADO]] -> 1268.85 | H12: =_xlfn.XLOOKUP(C12,'Telemetria Sighra'!F:F,'Telemetria Sighra'!R:R,0) -> 1913.85 | I12: =SUMIF(Faturamento!AC:AC,C12,Faturamento!T:T) -> 8660.51 | J12: {=SUMPRODUCT((ISNUMBER(FIND(C12,Faturamento!$F$2:$F$1014)))*(Faturamento!$R$2:$R$1014))} -> 145601 | K12: =$AH$2/30*$AA$1 -> 9479.7957 | L12: 4.4694 | M12: 40000 | N12: =Tabela1[[#This Row],[RESULTADO]]/Tabela1[[#This Row],[EBITDA ESTIMADO]] -> -0.23432617 | O12: =Tabela1[[#This Row],[FATURAMENTO]]-Tabela1[[#This Row],[CUSTO FIXO (SEM DEPREC.)]]-(Tabela1[[#This Row],[CUSTO VARIÁVEL]]*Tabela1[[#This Row],[HODÔMETRO]])+IF(COUNTIFS('ROTAS REALIZADAS'!A:A,Tabela1[[#This Row],[PLACA]],'ROTAS REALIZADAS'!A:A,"SANTOS/PAULINIA")>0,$AA$1*1233.33,0) -> -9373.0469 | P12: =IFERROR(Tabela1[[#This Row],[RESULTADO]]/Tabela1[[#This Row],[FATURAMENTO]],"-") -> -1.0822742 | Q12: =IFERROR(I12/H12,"-") -> 4.525177 | R12: =_xlfn.XLOOKUP(C12,'Telemetria Sighra'!F:F,'Telemetria Sighra'!S:S,0) -> 2.5586643 | S12: =_xlfn.XLOOKUP(Tabela1[[#This Row],[PLACA]],'Telemetria Sighra'!F:F,'Telemetria Sighra'!I:I,0) -> 748.07 | T12: =IFERROR((Tabela1[[#This Row],[LITROS CONSUMIDOS]]*$U$1)/Tabela1[[#This Row],[HODÔMETRO]],"-") -> 2.3452308
A13: DAF/XF FTT 530 | B13: 2024 | C13: SEX2C73 | D13: METANOL | E13: =IFERROR(_xlfn.XLOOKUP(Tabela1[[#This Row],[PLACA]],'Telemetria Sighra'!F:F,'Telemetria Sighra'!T:T),"NÃO EMBARCADO") -> MARIOVANY QUIRINO GOMES - 200 | F13: {=SUMPRODUCT((ISNUMBER(FIND(C13,Faturamento!$F$2:$F$1014)))*(Faturamento!$AA$2:$AA$1014))} -> 860 | G13: =Tabela1[[#This Row],[HODÔMETRO]]-Tabela1[[#This Row],[KM CARREGADO]] -> 1821.91 | H13: =_xlfn.XLOOKUP(C13,'Telemetria Sighra'!F:F,'Telemetria Sighra'!R:R,0) -> 2681.91 | I13: =SUMIF(Faturamento!AC:AC,C13,Faturamento!T:T) -> 12919.55 | J13: {=SUMPRODUCT((ISNUMBER(FIND(C13,Faturamento!$F$2:$F$1014)))*(Faturamento!$R$2:$R$1014))} -> 247926 | K13: =$AH$2/30*$AA$1 -> 9479.7957 | L13: 4.4694 | M13: 47896 | N13: =Tabela1[[#This Row],[RESULTADO]]/Tabela1[[#This Row],[EBITDA ESTIMADO]] -> -0.17844443 | O13: =Tabela1[[#This Row],[FATURAMENTO]]-Tabela1[[#This Row],[CUSTO FIXO (SEM DEPREC.)]]-(Tabela1[[#This Row],[CUSTO VARIÁVEL]]*Tabela1[[#This Row],[HODÔMETRO]])+IF(COUNTIFS('ROTAS REALIZADAS'!A:A,Tabela1[[#This Row],[PLACA]],'ROTAS REALIZADAS'!A:A,"SANTOS/PAULINIA")>0,$AA$1*1233.33,0) -> -8546.7743 | P13: =IFERROR(Tabela1[[#This Row],[RESULTADO]]/Tabela1[[#This Row],[FATURAMENTO]],"-") -> -0.66153808 | Q13: =IFERROR(I13/H13,"-") -> 4.8172944 | R13: =_xlfn.XLOOKUP(C13,'Telemetria Sighra'!F:F,'Telemetria Sighra'!S:S,0) -> 1.9951277 | S13: =_xlfn.XLOOKUP(Tabela1[[#This Row],[PLACA]],'Telemetria Sighra'!F:F,'Telemetria Sighra'!I:I,0) -> 1344.33 | T13: =IFERROR((Tabela1[[#This Row],[LITROS CONSUMIDOS]]*$U$1)/Tabela1[[#This Row],[HODÔMETRO]],"-") -> 3.0075506
A14: DAF/XF FTT 530 | B14: 2023 | C14: SEE2J92 | D14: VIBRA | E14: =IFERROR(_xlfn.XLOOKUP(Tabela1[[#This Row],[PLACA]],'Telemetria Sighra'!F:F,'Telemetria Sighra'!T:T),"NÃO EMBARCADO") -> SILAS DE LIMA - 225 | F14: {=SUMPRODUCT((ISNUMBER(FIND(C14,Faturamento!$F$2:$F$1014)))*(Faturamento!$AA$2:$AA$1014))} -> 860 | G14: =Tabela1[[#This Row],[HODÔMETRO]]-Tabela1[[#This Row],[KM CARREGADO]] -> 1524.76 | H14: =_xlfn.XLOOKUP(C14,'Telemetria Sighra'!F:F,'Telemetria Sighra'!R:R,0) -> 2384.76 | I14: =SUMIF(Faturamento!AC:AC,C14,Faturamento!T:T) -> 12599.78 | J14: {=SUMPRODUCT((ISNUMBER(FIND(C14,Faturamento!$F$2:$F$1014)))*(Faturamento!$R$2:$R$1014))} -> 246833 | K14: =$AH$2/30*$AA$1 -> 9479.7957 | L14: 4.4694 | M14: 69761 | N14: =Tabela1[[#This Row],[RESULTADO]]/Tabela1[[#This Row],[EBITDA ESTIMADO]] -> -0.10806127 | O14: =Tabela1[[#This Row],[FATURAMENTO]]-Tabela1[[#This Row],[CUSTO FIXO (SEM DEPREC.)]]-(Tabela1[[#This Row],[CUSTO VARIÁVEL]]*Tabela1[[#This Row],[HODÔMETRO]])+IF(COUNTIFS('ROTAS REALIZADAS'!A:A,Tabela1[[#This Row],[PLACA]],'ROTAS REALIZADAS'!A:A,"SANTOS/PAULINIA")>0,$AA$1*1233.33,0) -> -7538.4621 | P14: =IFERROR(Tabela1[[#This Row],[RESULTADO]]/Tabela1[[#This Row],[FATURAMENTO]],"-") -> -0.59830109 | Q14: =IFERROR(I14/H14,"-") -> 5.2834583 | R14: =_xlfn.XLOOKUP(C14,'Telemetria Sighra'!F:F,'Telemetria Sighra'!S:S,0) -> 2.1322695 | S14: =_xlfn.XLOOKUP(Tabela1[[#This Row],[PLACA]],'Telemetria Sighra'!F:F,'Telemetria Sighra'!I:I,0) -> 1118.55 | T14: =IFERROR((Tabela1[[#This Row],[LITROS CONSUMIDOS]]*$U$1)/Tabela1[[#This Row],[HODÔMETRO]],"-") -> 2.8142455
A15: DAF/XF FTT 530 | B15: 2023 | C15: SEE2J86 | D15: SANTOS X PAULINIA | E15: =IFERROR(_xlfn.XLOOKUP(Tabela1[[#This Row],[PLACA]],'Telemetria Sighra'!F:F,'Telemetria Sighra'!T:T),"NÃO EMBARCADO") -> SAMUEL CRUZ TORRES DE BRITO - 189 | F15: {=SUMPRODUCT((ISNUMBER(FIND(C15,Faturamento!$F$2:$F$1014)))*(Faturamento!$AA$2:$AA$1014))} -> 860 | G15: =Tabela1[[#This Row],[HODÔMETRO]]-Tabela1[[#This Row],[KM CARREGADO]] -> 1138.54 | H15: =_xlfn.XLOOKUP(C15,'Telemetria Sighra'!F:F,'Telemetria Sighra'!R:R,0) -> 1998.54 | I15: =SUMIF(Faturamento!AC:AC,C15,Faturamento!T:T) -> 12600.12 | J15: {=SUMPRODUCT((ISNUMBER(FIND(C15,Faturamento!$F$2:$F$1014)))*(Faturamento!$R$2:$R$1014))} -> 247201 | K15: =$AH$2/30*$AA$1 -> 9479.7957 | L15: 4.4694 | M15: 39990 | N15: =Tabela1[[#This Row],[RESULTADO]]/Tabela1[[#This Row],[EBITDA ESTIMADO]] -> -0.14533509 | O15: =Tabela1[[#This Row],[FATURAMENTO]]-Tabela1[[#This Row],[CUSTO FIXO (SEM DEPREC.)]]-(Tabela1[[#This Row],[CUSTO VARIÁVEL]]*Tabela1[[#This Row],[HODÔMETRO]])+IF(COUNTIFS('ROTAS REALIZADAS'!A:A,Tabela1[[#This Row],[PLACA]],'ROTAS REALIZADAS'!A:A,"SANTOS/PAULINIA")>0,$AA$1*1233.33,0) -> -5811.9504 | P15: =IFERROR(Tabela1[[#This Row],[RESULTADO]]/Tabela1[[#This Row],[FATURAMENTO]],"-") -> -0.46126151 | Q15: =IFERROR(I15/H15,"-") -> 6.3046624 | R15: =_xlfn.XLOOKUP(C15,'Telemetria Sighra'!F:F,'Telemetria Sighra'!S:S,0) -> 2.0687367 | S15: =_xlfn.XLOOKUP(Tabela1[[#This Row],[PLACA]],'Telemetria Sighra'!F:F,'Telemetria Sighra'!I:I,0) -> 966.15 | T15: =IFERROR((Tabela1[[#This Row],[LITROS CONSUMIDOS]]*$U$1)/Tabela1[[#This Row],[HODÔMETRO]],"-") -> 2.9005674
A16: DAF/XF FTT 530 | B16: 2023 | C16: SEE0H97 | D16: CAMERA | E16: =IFERROR(_xlfn.XLOOKUP(Tabela1[[#This Row],[PLACA]],'Telemetria Sighra'!F:F,'Telemetria Sighra'!T:T),"NÃO EMBARCADO") -> JOSE CLAUDIO DA CRUZ - 201 | F16: {=SUMPRODUCT((ISNUMBER(FIND(C16,Faturamento!$F$2:$F$1014)))*(Faturamento!$AA$2:$AA$1014))} -> 580 | G16: =Tabela1[[#This Row],[HODÔMETRO]]-Tabela1[[#This Row],[KM CARREGADO]] -> 186.37 | H16: =_xlfn.XLOOKUP(C16,'Telemetria Sighra'!F:F,'Telemetria Sighra'!R:R,0) -> 766.37 | I16: =SUMIF(Faturamento!AC:AC,C16,Faturamento!T:T) -> 8338.09 | J16: {=SUMPRODUCT((ISNUMBER(FIND(C16,Faturamento!$F$2:$F$1014)))*(Faturamento!$R$2:$R$1014))} -> 59250 | K16: =$AH$2/30*$AA$1 -> 9479.7957 | L16: 4.4694 | M16: 53428 | N16: =Tabela1[[#This Row],[RESULTADO]]/Tabela1[[#This Row],[EBITDA ESTIMADO]] -> -0.085478023 | O16: =Tabela1[[#This Row],[FATURAMENTO]]-Tabela1[[#This Row],[CUSTO FIXO (SEM DEPREC.)]]-(Tabela1[[#This Row],[CUSTO VARIÁVEL]]*Tabela1[[#This Row],[HODÔMETRO]])+IF(COUNTIFS('ROTAS REALIZADAS'!A:A,Tabela1[[#This Row],[PLACA]],'ROTAS REALIZADAS'!A:A,"SANTOS/PAULINIA")>0,$AA$1*1233.33,0) -> -4566.9198 | P16: =IFERROR(Tabela1[[#This Row],[RESULTADO]]/Tabela1[[#This Row],[FATURAMENTO]],"-") -> -0.54771774 | Q16: =IFERROR(I16/H16,"-") -> 10.87998 | R16: =_xlfn.XLOOKUP(C16,'Telemetria Sighra'!F:F,'Telemetria Sighra'!S:S,0) -> 1.2623518 | S16: =_xlfn.XLOOKUP(Tabela1[[#This Row],[PLACA]],'Telemetria Sighra'!F:F,'Telemetria Sighra'!I:I,0) -> 607.2 | T16: =IFERROR((Tabela1[[#This Row],[LITROS CONSUMIDOS]]*$U$1)/Tabela1[[#This Row],[HODÔMETRO]],"-") -> 4.7538395
A17: VOLVO/FH 540 6X4T | B17: 2020 | C17: BDQ4E19 | D17: SANTOS X PAULINIA | E17: =IFERROR(_xlfn.XLOOKUP(Tabela1[[#This Row],[PLACA]],'Telemetria Sighra'!F:F,'Telemetria Sighra'!T:T),"NÃO EMBARCADO") -> ADRIANO DAGNON - 247 | F17: {=SUMPRODUCT((ISNUMBER(FIND(C17,Faturamento!$F$2:$F$1014)))*(Faturamento!$AA$2:$AA$1014))} -> 1076 | G17: =Tabela1[[#This Row],[HODÔMETRO]]-Tabela1[[#This Row],[KM CARREGADO]] -> 1945.86 | H17: =_xlfn.XLOOKUP(C17,'Telemetria Sighra'!F:F,'Telemetria Sighra'!R:R,0) -> 3021.86 | I17: =SUMIF(Faturamento!AC:AC,C17,Faturamento!T:T) -> 18675.3 | J17: {=SUMPRODUCT((ISNUMBER(FIND(C17,Faturamento!$F$2:$F$1014)))*(Faturamento!$R$2:$R$1014))} -> 105728 | K17: =$AH$2/30*$AA$1 -> 9479.7957 | L17: 4.4694 | M17: 39990 | N17: =Tabela1[[#This Row],[RESULTADO]]/Tabela1[[#This Row],[EBITDA ESTIMADO]] -> -0.10778687 | O17: =Tabela1[[#This Row],[FATURAMENTO]]-Tabela1[[#This Row],[CUSTO FIXO (SEM DEPREC.)]]-(Tabela1[[#This Row],[CUSTO VARIÁVEL]]*Tabela1[[#This Row],[HODÔMETRO]])+IF(COUNTIFS('ROTAS REALIZADAS'!A:A,Tabela1[[#This Row],[PLACA]],'ROTAS REALIZADAS'!A:A,"SANTOS/PAULINIA")>0,$AA$1*1233.33,0) -> -4310.3968 | P17: =IFERROR(Tabela1[[#This Row],[RESULTADO]]/Tabela1[[#This Row],[FATURAMENTO]],"-") -> -0.23080737 | Q17: =IFERROR(I17/H17,"-") -> 6.1800679 | R17: =_xlfn.XLOOKUP(C17,'Telemetria Sighra'!F:F,'Telemetria Sighra'!S:S,0) -> 1.578471 | S17: =_xlfn.XLOOKUP(Tabela1[[#This Row],[PLACA]],'Telemetria Sighra'!F:F,'Telemetria Sighra'!I:I,0) -> 1914.53 | T17: =IFERROR((Tabela1[[#This Row],[LITROS CONSUMIDOS]]*$U$1)/Tabela1[[#This Row],[HODÔMETRO]],"-") -> 3.8013608
A18: DAF/XF FTT 530 | B18: 2023 | C18: SEE0I16 | D18: ISOTANK | E18: =IFERROR(_xlfn.XLOOKUP(Tabela1[[#This Row],[PLACA]],'Telemetria Sighra'!F:F,'Telemetria Sighra'!T:T),"NÃO EMBARCADO") -> LEANDRO CESAR VIEIRA DE OLIVEIRA - 1 | F18: {=SUMPRODUCT((ISNUMBER(FIND(C18,Faturamento!$F$2:$F$1014)))*(Faturamento!$AA$2:$AA$1014))} -> 2055 | G18: =Tabela1[[#This Row],[HODÔMETRO]]-Tabela1[[#This Row],[KM CARREGADO]] -> 602.47 | H18: =_xlfn.XLOOKUP(C18,'Telemetria Sighra'!F:F,'Telemetria Sighra'!R:R,0) -> 2657.47 | I18: =SUMIF(Faturamento!AC:AC,C18,Faturamento!T:T) -> 17096.65 | J18: {=SUMPRODUCT((ISNUMBER(FIND(C18,Faturamento!$F$2:$F$1014)))*(Faturamento!$R$2:$R$1014))} -> 152090 | K18: =$AH$2/30*$AA$1 -> 9479.7957 | L18: 4.4694 | M18: 40000 | N18: =Tabela1[[#This Row],[RESULTADO]]/Tabela1[[#This Row],[EBITDA ESTIMADO]] -> -0.10651105 | O18: =Tabela1[[#This Row],[FATURAMENTO]]-Tabela1[[#This Row],[CUSTO FIXO (SEM DEPREC.)]]-(Tabela1[[#This Row],[CUSTO VARIÁVEL]]*Tabela1[[#This Row],[HODÔMETRO]])+IF(COUNTIFS('ROTAS REALIZADAS'!A:A,Tabela1[[#This Row],[PLACA]],'ROTAS REALIZADAS'!A:A,"SANTOS/PAULINIA")>0,$AA$1*1233.33,0) -> -4260.4421 | P18: =IFERROR(Tabela1[[#This Row],[RESULTADO]]/Tabela1[[#This Row],[FATURAMENTO]],"-") -> -0.24919748 | Q18: =IFERROR(I18/H18,"-") -> 6.433431 | R18: =_xlfn.XLOOKUP(C18,'Telemetria Sighra'!F:F,'Telemetria Sighra'!S:S,0) -> 1.9377415 | S18: =_xlfn.XLOOKUP(Tabela1[[#This Row],[PLACA]],'Telemetria Sighra'!F:F,'Telemetria Sighra'!I:I,0) -> 1371.54 | T18: =IFERROR((Tabela1[[#This Row],[LITROS CONSUMIDOS]]*$U$1)/Tabela1[[#This Row],[HODÔMETRO]],"-") -> 3.0966446
A19: DAF/XF FTT 530 | B19: 2021 | C19: RHG5D75 | D19: ISOTANK | E19: =IFERROR(_xlfn.XLOOKUP(Tabela1[[#This Row],[PLACA]],'Telemetria Sighra'!F:F,'Telemetria Sighra'!T:T),"NÃO EMBARCADO") -> VILSO DE OLIVEIRA COSTA - 78 | F19: {=SUMPRODUCT((ISNUMBER(FIND(C19,Faturamento!$F$2:$F$1014)))*(Faturamento!$AA$2:$AA$1014))} -> 1860 | G19: =Tabela1[[#This Row],[HODÔMETRO]]-Tabela1[[#This Row],[KM CARREGADO]] -> -793.74 | H19: =_xlfn.XLOOKUP(C19,'Telemetria Sighra'!F:F,'Telemetria Sighra'!R:R,0) -> 1066.26 | I19: =SUMIF(Faturamento!AC:AC,C19,Faturamento!T:T) -> 10600 | J19: {=SUMPRODUCT((ISNUMBER(FIND(C19,Faturamento!$F$2:$F$1014)))*(Faturamento!$R$2:$R$1014))} -> 107140 | K19: =$AH$2/30*$AA$1 -> 9479.7957 | L19: 4.4694 | M19: 40000 | N19: =Tabela1[[#This Row],[RESULTADO]]/Tabela1[[#This Row],[EBITDA ESTIMADO]] -> -0.091133454 | O19: =Tabela1[[#This Row],[FATURAMENTO]]-Tabela1[[#This Row],[CUSTO FIXO (SEM DEPREC.)]]-(Tabela1[[#This Row],[CUSTO VARIÁVEL]]*Tabela1[[#This Row],[HODÔMETRO]])+IF(COUNTIFS('ROTAS REALIZADAS'!A:A,Tabela1[[#This Row],[PLACA]],'ROTAS REALIZADAS'!A:A,"SANTOS/PAULINIA")>0,$AA$1*1233.33,0) -> -3645.3382 | P19: =IFERROR(Tabela1[[#This Row],[RESULTADO]]/Tabela1[[#This Row],[FATURAMENTO]],"-") -> -0.34389983 | Q19: =IFERROR(I19/H19,"-") -> 9.9412901 | R19: =_xlfn.XLOOKUP(C19,'Telemetria Sighra'!F:F,'Telemetria Sighra'!S:S,0) -> 2.0141832 | S19: =_xlfn.XLOOKUP(Tabela1[[#This Row],[PLACA]],'Telemetria Sighra'!F:F,'Telemetria Sighra'!I:I,0) -> 529.5 | T19: =IFERROR((Tabela1[[#This Row],[LITROS CONSUMIDOS]]*$U$1)/Tabela1[[#This Row],[HODÔMETRO]],"-") -> 2.9795735
... A24: DAF/XF FTT 530 | B24: 2021 | C24: BEZ9A98 | D24: ISOTANK | E24: =IFERROR(_xlfn.XLOOKUP(Tabela1[[#This Row],[PLACA]],'Telemetria Sighra'!F:F,'Telemetria Sighra'!T:T),"NÃO EMBARCADO") -> ISACC SANTOS GUEDES - 172 | F24: {=SUMPRODUCT((ISNUMBER(FIND(C24,Faturamento!$F$2:$F$1014)))*(Faturamento!$AA$2:$AA$1014))} -> 2055 | G24: =Tabela1[[#This Row],[HODÔMETRO]]-Tabela1[[#This Row],[KM CARREGADO]] -> 286.38 | H24: =_xlfn.XLOOKUP(C24,'Telemetria Sighra'!F:F,'Telemetria Sighra'!R:R,0) -> 2341.38 | I24: =SUMIF(Faturamento!AC:AC,C24,Faturamento!T:T) -> 17140.1 | J24: {=SUMPRODUCT((ISNUMBER(FIND(C24,Faturamento!$F$2:$F$1014)))*(Faturamento!$R$2:$R$1014))} -> 151820 | K24: =$AH$2/30*$AA$1 -> 9479.7957 | L24: 4.4694 | M24: 40000 | N24: =Tabela1[[#This Row],[RESULTADO]]/Tabela1[[#This Row],[EBITDA ESTIMADO]] -> -0.070106487 | O24: =Tabela1[[#This Row],[FATURAMENTO]]-Tabela1[[#This Row],[CUSTO FIXO (SEM DEPREC.)]]-(Tabela1[[#This Row],[CUSTO VARIÁVEL]]*Tabela1[[#This Row],[HODÔMETRO]])+IF(COUNTIFS('ROTAS REALIZADAS'!A:A,Tabela1[[#This Row],[PLACA]],'ROTAS REALIZADAS'!A:A,"SANTOS/PAULINIA")>0,$AA$1*1233.33,0) -> -2804.2595 | P24: =IFERROR(Tabela1[[#This Row],[RESULTADO]]/Tabela1[[#This Row],[FATURAMENTO]],"-") -> -0.16360812 | Q24: =IFERROR(I24/H24,"-") -> 7.3205118 | R24: =_xlfn.XLOOKUP(C24,'Telemetria Sighra'!F:F,'Telemetria Sighra'!S:S,0) -> 1.6041996 | S24: =_xlfn.XLOOKUP(Tabela1[[#This Row],[PLACA]],'Telemetria Sighra'!F:F,'Telemetria Sighra'!I:I,0) -> 1459.65 | T24: =IFERROR((Tabela1[[#This Row],[LITROS CONSUMIDOS]]*$U$1)/Tabela1[[#This Row],[HODÔMETRO]],"-") -> 3.7404864
A25: SCANIA/R 480 A6X4 | B25: 2017 | C25: BBM5I45 | D25: METANOL | E25: =IFERROR(_xlfn.XLOOKUP(Tabela1[[#This Row],[PLACA]],'Telemetria Sighra'!F:F,'Telemetria Sighra'!T:T),"NÃO EMBARCADO") -> VLADEMIR JORGE SANTOS - 208 | F25: {=SUMPRODUCT((ISNUMBER(FIND(C25,Faturamento!$F$2:$F$1014)))*(Faturamento!$AA$2:$AA$1014))} -> 1003 | G25: =Tabela1[[#This Row],[HODÔMETRO]]-Tabela1[[#This Row],[KM CARREGADO]] -> 1521.67 | H25: =_xlfn.XLOOKUP(C25,'Telemetria Sighra'!F:F,'Telemetria Sighra'!R:R,0) -> 2524.67 | I25: =SUMIF(Faturamento!AC:AC,C25,Faturamento!T:T) -> 14527.51 | J25: {=SUMPRODUCT((ISNUMBER(FIND(C25,Faturamento!$F$2:$F$1014)))*(Faturamento!$R$2:$R$1014))} -> 128653 | K25: =$AD$2/30*$AA$1 -> 7856.0195 | L25: 3.55 | M25: 47896 | N25: =Tabela1[[#This Row],[RESULTADO]]/Tabela1[[#This Row],[EBITDA ESTIMADO]] -> -0.047834642 | O25: =Tabela1[[#This Row],[FATURAMENTO]]-Tabela1[[#This Row],[CUSTO FIXO (SEM DEPREC.)]]-(Tabela1[[#This Row],[CUSTO VARIÁVEL]]*Tabela1[[#This Row],[HODÔMETRO]])+IF(COUNTIFS('ROTAS REALIZADAS'!A:A,Tabela1[[#This Row],[PLACA]],'ROTAS REALIZADAS'!A:A,"SANTOS/PAULINIA")>0,$AA$1*1233.33,0) -> -2291.088 | P25: =IFERROR(Tabela1[[#This Row],[RESULTADO]]/Tabela1[[#This Row],[FATURAMENTO]],"-") -> -0.15770686 | Q25: =IFERROR(I25/H25,"-") -> 5.7542213 | R25: =_xlfn.XLOOKUP(C25,'Telemetria Sighra'!F:F,'Telemetria Sighra'!S:S,0) -> 2.3209877 | S25: =_xlfn.XLOOKUP(Tabela1[[#This Row],[PLACA]],'Telemetria Sighra'!F:F,'Telemetria Sighra'!I:I,0) -> 1087.83 | T25: =IFERROR((Tabela1[[#This Row],[LITROS CONSUMIDOS]]*$U$1)/Tabela1[[#This Row],[HODÔMETRO]],"-") -> 2.5852805
A26: DAF/XF FTT 530 | B26: 2023 | C26: SEE2J87 | D26: SANTOS X PAULINIA | E26: =IFERROR(_xlfn.XLOOKUP(Tabela1[[#This Row],[PLACA]],'Telemetria Sighra'!F:F,'Telemetria Sighra'!T:T),"NÃO EMBARCADO") -> LUIZ CEZAR KELCZESKI - 50073 | F26: {=SUMPRODUCT((ISNUMBER(FIND(C26,Faturamento!$F$2:$F$1014)))*(Faturamento!$AA$2:$AA$1014))} -> 1212 | G26: =Tabela1[[#This Row],[HODÔMETRO]]-Tabela1[[#This Row],[KM CARREGADO]] -> 892.04 | H26: =_xlfn.XLOOKUP(C26,'Telemetria Sighra'!F:F,'Telemetria Sighra'!R:R,0) -> 2104.04 | I26: =SUMIF(Faturamento!AC:AC,C26,Faturamento!T:T) -> 17284.1 | J26: {=SUMPRODUCT((ISNUMBER(FIND(C26,Faturamento!$F$2:$F$1014)))*(Faturamento!$R$2:$R$1014))} -> 57345 | K26: =$AH$2/30*$AA$1 -> 9479.7957 | L26: 4.4694 | M26: 39990 | N26: =Tabela1[[#This Row],[RESULTADO]]/Tabela1[[#This Row],[EBITDA ESTIMADO]] -> -0.039997302 | O26: =Tabela1[[#This Row],[FATURAMENTO]]-Tabela1[[#This Row],[CUSTO FIXO (SEM DEPREC.)]]-(Tabela1[[#This Row],[CUSTO VARIÁVEL]]*Tabela1[[#This Row],[HODÔMETRO]])+IF(COUNTIFS('ROTAS REALIZADAS'!A:A,Tabela1[[#This Row],[PLACA]],'ROTAS REALIZADAS'!A:A,"SANTOS/PAULINIA")>0,$AA$1*1233.33,0) -> -1599.4921 | P26: =IFERROR(Tabela1[[#This Row],[RESULTADO]]/Tabela1[[#This Row],[FATURAMENTO]],"-") -> -0.092541243 | Q26: =IFERROR(I26/H26,"-") -> 8.2147203 | R26: =_xlfn.XLOOKUP(C26,'Telemetria Sighra'!F:F,'Telemetria Sighra'!S:S,0) -> 1.0146153 | S26: =_xlfn.XLOOKUP(Tabela1[[#This Row],[PLACA]],'Telemetria Sighra'!F:F,'Telemetria Sighra'!I:I,0) -> 2073.85 | T26: =IFERROR((Tabela1[[#This Row],[LITROS CONSUMIDOS]]*$U$1)/Tabela1[[#This Row],[HODÔMETRO]],"-") -> 5.9139085
A27: DAF/XF FTT 530 | B27: 2024 | C27: SEX2C75 | D27: SANTOS X PAULINIA | E27: =IFERROR(_xlfn.XLOOKUP(Tabela1[[#This Row],[PLACA]],'Telemetria Sighra'!F:F,'Telemetria Sighra'!T:T),"NÃO EMBARCADO") -> FRANCISCO JOSE ESTEVES - 162 | F27: {=SUMPRODUCT((ISNUMBER(FIND(C27,Faturamento!$F$2:$F$1014)))*(Faturamento!$AA$2:$AA$1014))} -> 1346 | G27: =Tabela1[[#This Row],[HODÔMETRO]]-Tabela1[[#This Row],[KM CARREGADO]] -> 1413.25 | H27: =_xlfn.XLOOKUP(C27,'Telemetria Sighra'!F:F,'Telemetria Sighra'!R:R,0) -> 2759.25 | I27: =SUMIF(Faturamento!AC:AC,C27,Faturamento!T:T) -> 20288.44 | J27: {=SUMPRODUCT((ISNUMBER(FIND(C27,Faturamento!$F$2:$F$1014)))*(Faturamento!$R$2:$R$1014))} -> 245307 | K27: =$AH$2/30*$AA$1 -> 9479.7957 | L27: 4.4694 | M27: 39990 | N27: =Tabela1[[#This Row],[RESULTADO]]/Tabela1[[#This Row],[EBITDA ESTIMADO]] -> -0.038098216 | O27: =Tabela1[[#This Row],[FATURAMENTO]]-Tabela1[[#This Row],[CUSTO FIXO (SEM DEPREC.)]]-(Tabela1[[#This Row],[CUSTO VARIÁVEL]]*Tabela1[[#This Row],[HODÔMETRO]])+IF(COUNTIFS('ROTAS REALIZADAS'!A:A,Tabela1[[#This Row],[PLACA]],'ROTAS REALIZADAS'!A:A,"SANTOS/PAULINIA")>0,$AA$1*1233.33,0) -> -1523.5477 | P27: =IFERROR(Tabela1[[#This Row],[RESULTADO]]/Tabela1[[#This Row],[FATURAMENTO]],"-") -> -0.075094373 | Q27: =IFERROR(I27/H27,"-") -> 7.3528821 | R27: =_xlfn.XLOOKUP(C27,'Telemetria Sighra'!F:F,'Telemetria Sighra'!S:S,0) -> 1.8247753 | S27: =_xlfn.XLOOKUP(Tabela1[[#This Row],[PLACA]],'Telemetria Sighra'!F:F,'Telemetria Sighra'!I:I,0) -> 1512.23 | T27: =IFERROR((Tabela1[[#This Row],[LITROS CONSUMIDOS]]*$U$1)/Tabela1[[#This Row],[HODÔMETRO]],"-") -> 3.2883501
A28: VOLVO/FH 540 6X4T | B28: 2020 | C28: BDQ4E18 | D28: SANTOS X PAULINIA | E28: =IFERROR(_xlfn.XLOOKUP(Tabela1[[#This Row],[PLACA]],'Telemetria Sighra'!F:F,'Telemetria Sighra'!T:T),"NÃO EMBARCADO") -> DANIEL EUFRAZIO - 245 | F28: {=SUMPRODUCT((ISNUMBER(FIND(C28,Faturamento!$F$2:$F$1014)))*(Faturamento!$AA$2:$AA$1014))} -> 1138 | G28: =Tabela1[[#This Row],[HODÔMETRO]]-Tabela1[[#This Row],[KM CARREGADO]] -> 533 | H28: =_xlfn.XLOOKUP(C28,'Telemetria Sighra'!F:F,'Telemetria Sighra'!R:R,0) -> 1671 | I28: =SUMIF(Faturamento!AC:AC,C28,Faturamento!T:T) -> 15955.98 | J28: {=SUMPRODUCT((ISNUMBER(FIND(C28,Faturamento!$F$2:$F$1014)))*(Faturamento!$R$2:$R$1014))} -> 117574 | K28: =$AH$2/30*$AA$1 -> 9479.7957 | L28: 4.4694 | M28: 39990 | N28: =Tabela1[[#This Row],[RESULTADO]]/Tabela1[[#This Row],[EBITDA ESTIMADO]] -> -0.024810781 | O28: =Tabela1[[#This Row],[FATURAMENTO]]-Tabela1[[#This Row],[CUSTO FIXO (SEM DEPREC.)]]-(Tabela1[[#This Row],[CUSTO VARIÁVEL]]*Tabela1[[#This Row],[HODÔMETRO]])+IF(COUNTIFS('ROTAS REALIZADAS'!A:A,Tabela1[[#This Row],[PLACA]],'ROTAS REALIZADAS'!A:A,"SANTOS/PAULINIA")>0,$AA$1*1233.33,0) -> -992.18312 | P28: =IFERROR(Tabela1[[#This Row],[RESULTADO]]/Tabela1[[#This Row],[FATURAMENTO]],"-") -> -0.062182525 | Q28: =IFERROR(I28/H28,"-") -> 9.5487612 | R28: =_xlfn.XLOOKUP(C28,'Telemetria Sighra'!F:F,'Telemetria Sighra'!S:S,0) -> 1.2932705 | S28: =_xlfn.XLOOKUP(Tabela1[[#This Row],[PLACA]],'Telemetria Sighra'!F:F,'Telemetria Sighra'!I:I,0) -> 1292.22 | T28: =IFERROR((Tabela1[[#This Row],[LITROS CONSUMIDOS]]*$U$1)/Tabela1[[#This Row],[HODÔMETRO]],"-") -> 4.6399282
A29: DAF/XF FTT 530 | B29: 2023 | C29: SEE0I13 | D29: Spot melhor tarifa | E29: =IFERROR(_xlfn.XLOOKUP(Tabela1[[#This Row],[PLACA]],'Telemetria Sighra'!F:F,'Telemetria Sighra'!T:T),"NÃO EMBARCADO") -> ALAOR BATISTA DE FREITAS - 193 | F29: {=SUMPRODUCT((ISNUMBER(FIND(C29,Faturamento!$F$2:$F$1014)))*(Faturamento!$AA$2:$AA$1014))} -> 1286 | G29: =Tabela1[[#This Row],[HODÔMETRO]]-Tabela1[[#This Row],[KM CARREGADO]] -> 1576.74 | H29: =_xlfn.XLOOKUP(C29,'Telemetria Sighra'!F:F,'Telemetria Sighra'!R:R,0) -> 2862.74 | I29: =SUMIF(Faturamento!AC:AC,C29,Faturamento!T:T) -> 21626.84 | J29: {=SUMPRODUCT((ISNUMBER(FIND(C29,Faturamento!$F$2:$F$1014)))*(Faturamento!$R$2:$R$1014))} -> 245397 | K29: =$AH$2/30*$AA$1 -> 9479.7957 | L29: 4.4694 | M29: 40000 | N29: =Tabela1[[#This Row],[RESULTADO]]/Tabela1[[#This Row],[EBITDA ESTIMADO]] -> -0.016192147 | O29: =Tabela1[[#This Row],[FATURAMENTO]]-Tabela1[[#This Row],[CUSTO FIXO (SEM DEPREC.)]]-(Tabela1[[#This Row],[CUSTO VARIÁVEL]]*Tabela1[[#This Row],[HODÔMETRO]])+IF(COUNTIFS('ROTAS REALIZADAS'!A:A,Tabela1[[#This Row],[PLACA]],'ROTAS REALIZADAS'!A:A,"SANTOS/PAULINIA")>0,$AA$1*1233.33,0) -> -647.68588 | P29: =IFERROR(Tabela1[[#This Row],[RESULTADO]]/Tabela1[[#This Row],[FATURAMENTO]],"-") -> -0.029948244 | Q29: =IFERROR(I29/H29,"-") -> 7.5545945 | R29: =_xlfn.XLOOKUP(C29,'Telemetria Sighra'!F:F,'Telemetria Sighra'!S:S,0) -> 1.2487201 | S29: =_xlfn.XLOOKUP(Tabela1[[#This Row],[PLACA]],'Telemetria Sighra'!F:F,'Telemetria Sighra'!I:I,0) -> 1511.78 | T29: =IFERROR((Tabela1[[#This Row],[LITROS CONSUMIDOS]]*$U$1)/Tabela1[[#This Row],[HODÔMETRO]],"-") -> 3.1685308
A30: DAF/XF FTT 530 | B30: 2023 | C30: SEE2J90 | D30: Spot melhor tarifa | E30: =IFERROR(_xlfn.XLOOKUP(Tabela1[[#This Row],[PLACA]],'Telemetria Sighra'!F:F,'Telemetria Sighra'!T:T),"NÃO EMBARCADO") -> ANDRIELIA APARECIDA GOMES - 238 | F30: {=SUMPRODUCT((ISNUMBER(FIND(C30,Faturamento!$F$2:$F$1014)))*(Faturamento!$AA$2:$AA$1014))} -> 1346 | G30: =Tabela1[[#This Row],[HODÔMETRO]]-Tabela1[[#This Row],[KM CARREGADO]] -> 1136.62 | H30: =_xlfn.XLOOKUP(C30,'Telemetria Sighra'!F:F,'Telemetria Sighra'!R:R,0) -> 2482.62 | I30: =SUMIF(Faturamento!AC:AC,C30,Faturamento!T:T) -> 20289.85 | J30: {=SUMPRODUCT((ISNUMBER(FIND(C30,Faturamento!$F$2:$F$1014)))*(Faturamento!$R$2:$R$1014))} -> 243351 | K30: =$AH$2/30*$AA$1 -> 9479.7957 | L30: 4.4694 | M30: 40000 | N30: =Tabela1[[#This Row],[RESULTADO]]/Tabela1[[#This Row],[EBITDA ESTIMADO]] -> -0.0071441888 | O30: =Tabela1[[#This Row],[FATURAMENTO]]-Tabela1[[#This Row],[CUSTO FIXO (SEM DEPREC.)]]-(Tabela1[[#This Row],[CUSTO VARIÁVEL]]*Tabela1[[#This Row],[HODÔMETRO]])+IF(COUNTIFS('ROTAS REALIZADAS'!A:A,Tabela1[[#This Row],[PLACA]],'ROTAS REALIZADAS'!A:A,"SANTOS/PAULINIA")>0,$AA$1*1233.33,0) -> -285.76755 | P30: =IFERROR(Tabela1[[#This Row],[RESULTADO]]/Tabela1[[#This Row],[FATURAMENTO]],"-") -> -0.014084261 | Q30: =IFERROR(I30/H30,"-") -> 8.172757 | R30: =_xlfn.XLOOKUP(C30,'Telemetria Sighra'!F:F,'Telemetria Sighra'!S:S,0) -> 1.7649405 | S30: =_xlfn.XLOOKUP(Tabela1[[#This Row],[PLACA]],'Telemetria Sighra'!F:F,'Telemetria Sighra'!I:I,0) -> 1406.75 | T30: =IFERROR((Tabela1[[#This Row],[LITROS CONSUMIDOS]]*$U$1)/Tabela1[[#This Row],[HODÔMETRO]],"-") -> 3.3998357
A31: DAF/XF FTT 530 | B31: 2021 | C31: RHH5D97 | D31: SANTOS X PAULINIA | E31: =IFERROR(_xlfn.XLOOKUP(Tabela1[[#This Row],[PLACA]],'Telemetria Sighra'!F:F,'Telemetria Sighra'!T:T),"NÃO EMBARCADO") -> MARIO SERGIO DOS SANTOS ANDREOLA - 50101 | F31: {=SUMPRODUCT((ISNUMBER(FIND(C31,Faturamento!$F$2:$F$1014)))*(Faturamento!$AA$2:$AA$1014))} -> 1034 | G31: =Tabela1[[#This Row],[HODÔMETRO]]-Tabela1[[#This Row],[KM CARREGADO]] -> 589.47 | H31: =_xlfn.XLOOKUP(C31,'Telemetria Sighra'!F:F,'Telemetria Sighra'!R:R,0) -> 1623.47 | I31: =SUMIF(Faturamento!AC:AC,C31,Faturamento!T:T) -> 17166.08 | J31: {=SUMPRODUCT((ISNUMBER(FIND(C31,Faturamento!$F$2:$F$1014)))*(Faturamento!$R$2:$R$1014))} -> 59598 | K31: =$AH$2/30*$AA$1 -> 9479.7957 | L31: 4.4694 | M31: 39990 | N31: =Tabela1[[#This Row],[RESULTADO]]/Tabela1[[#This Row],[EBITDA ESTIMADO]] -> 0.010761377 | O31: =Tabela1[[#This Row],[FATURAMENTO]]-Tabela1[[#This Row],[CUSTO FIXO (SEM DEPREC.)]]-(Tabela1[[#This Row],[CUSTO VARIÁVEL]]*Tabela1[[#This Row],[HODÔMETRO]])+IF(COUNTIFS('ROTAS REALIZADAS'!A:A,Tabela1[[#This Row],[PLACA]],'ROTAS REALIZADAS'!A:A,"SANTOS/PAULINIA")>0,$AA$1*1233.33,0) -> 430.34746 | P31: =IFERROR(Tabela1[[#This Row],[RESULTADO]]/Tabela1[[#This Row],[FATURAMENTO]],"-") -> 0.025069641 | Q31: =IFERROR(I31/H31,"-") -> 10.573697 | R31: =_xlfn.XLOOKUP(C31,'Telemetria Sighra'!F:F,'Telemetria Sighra'!S:S,0) -> 1.3322584 | S31: =_xlfn.XLOOKUP(Tabela1[[#This Row],[PLACA]],'Telemetria Sighra'!F:F,'Telemetria Sighra'!I:I,0) -> 1218.66 | T31: =IFERROR((Tabela1[[#This Row],[LITROS CONSUMIDOS]]*$U$1)/Tabela1[[#This Row],[HODÔMETRO]],"-") -> 4.5039083
A32: SCANIA/R 480 A6X4 | B32: 2016 | C32: BAX9A94 | D32: PGUA X LAPA | E32: =IFERROR(_xlfn.XLOOKUP(Tabela1[[#This Row],[PLACA]],'Telemetria Sighra'!F:F,'Telemetria Sighra'!T:T),"NÃO EMBARCADO") -> FRANCISCO ADEMIR MORO JUNIOR - 216 | F32: {=SUMPRODUCT((ISNUMBER(FIND(C32,Faturamento!$F$2:$F$1014)))*(Faturamento!$AA$2:$AA$1014))} -> 1346 | G32: =Tabela1[[#This Row],[HODÔMETRO]]-Tabela1[[#This Row],[KM CARREGADO]] -> 1326.63 | H32: =_xlfn.XLOOKUP(C32,'Telemetria Sighra'!F:F,'Telemetria Sighra'!R:R,0) -> 2672.63 | I32: =SUMIF(Faturamento!AC:AC,C32,Faturamento!T:T) -> 17938.65 | J32: {=SUMPRODUCT((ISNUMBER(FIND(C32,Faturamento!$F$2:$F$1014)))*(Faturamento!$R$2:$R$1014))} -> 189190 | K32: =$AD$2/30*$AA$1 -> 7856.0195 | L32: 3.55 | M32: 63000 | N32: =Tabela1[[#This Row],[RESULTADO]]/Tabela1[[#This Row],[EBITDA ESTIMADO]] -> 0.0094411742 | O32: =Tabela1[[#This Row],[FATURAMENTO]]-Tabela1[[#This Row],[CUSTO FIXO (SEM DEPREC.)]]-(Tabela1[[#This Row],[CUSTO VARIÁVEL]]*Tabela1[[#This Row],[HODÔMETRO]])+IF(COUNTIFS('ROTAS REALIZADAS'!A:A,Tabela1[[#This Row],[PLACA]],'ROTAS REALIZADAS'!A:A,"SANTOS/PAULINIA")>0,$AA$1*1233.33,0) -> 594.79397 | P32: =IFERROR(Tabela1[[#This Row],[RESULTADO]]/Tabela1[[#This Row],[FATURAMENTO]],"-") -> 0.03315712 | Q32: =IFERROR(I32/H32,"-") -> 6.7119841 | R32: =_xlfn.XLOOKUP(C32,'Telemetria Sighra'!F:F,'Telemetria Sighra'!S:S,0) -> 2.2072471 | S32: =_xlfn.XLOOKUP(Tabela1[[#This Row],[PLACA]],'Telemetria Sighra'!F:F,'Telemetria Sighra'!I:I,0) -> 1210.97 | T32: =IFERROR((Tabela1[[#This Row],[LITROS CONSUMIDOS]]*$U$1)/Tabela1[[#This Row],[HODÔMETRO]],"-") -> 2.718603
A33: VOLVO/FH 500 6X4T S BIO | B33: 2025 | C33: TAW8B84 | D33: VIBRA | E33: =IFERROR(_xlfn.XLOOKUP(Tabela1[[#This Row],[PLACA]],'Telemetria Sighra'!F:F,'Telemetria Sighra'!T:T),"NÃO EMBARCADO") -> EDENIR MALOSTI PEREIRA - 72 | F33: {=SUMPRODUCT((ISNUMBER(FIND(C33,Faturamento!$F$2:$F$1014)))*(Faturamento!$AA$2:$AA$1014))} -> 1506 | G33: =Tabela1[[#This Row],[HODÔMETRO]]-Tabela1[[#This Row],[KM CARREGADO]] -> 1777.4 | H33: =_xlfn.XLOOKUP(C33,'Telemetria Sighra'!F:F,'Telemetria Sighra'!R:R,0) -> 3283.4 | I33: =SUMIF(Faturamento!AC:AC,C33,Faturamento!T:T) -> 25037.32 | J33: {=SUMPRODUCT((ISNUMBER(FIND(C33,Faturamento!$F$2:$F$1014)))*(Faturamento!$R$2:$R$1014))} -> 234308 | K33: =$AH$2/30*$AA$1 -> 9479.7957 | L33: 4.4694 | M33: 69761 | N33: =Tabela1[[#This Row],[RESULTADO]]/Tabela1[[#This Row],[EBITDA ESTIMADO]] -> 0.012653149 | O33: =Tabela1[[#This Row],[FATURAMENTO]]-Tabela1[[#This Row],[CUSTO FIXO (SEM DEPREC.)]]-(Tabela1[[#This Row],[CUSTO VARIÁVEL]]*Tabela1[[#This Row],[HODÔMETRO]])+IF(COUNTIFS('ROTAS REALIZADAS'!A:A,Tabela1[[#This Row],[PLACA]],'ROTAS REALIZADAS'!A:A,"SANTOS/PAULINIA")>0,$AA$1*1233.33,0) -> 882.69632 | P33: =IFERROR(Tabela1[[#This Row],[RESULTADO]]/Tabela1[[#This Row],[FATURAMENTO]],"-") -> 0.035255224 | Q33: =IFERROR(I33/H33,"-") -> 7.6254249 | R33: =_xlfn.XLOOKUP(C33,'Telemetria Sighra'!F:F,'Telemetria Sighra'!S:S,0) -> 1.869535 | S33: =_xlfn.XLOOKUP(Tabela1[[#This Row],[PLACA]],'Telemetria Sighra'!F:F,'Telemetria Sighra'!I:I,0) -> 1756.41 | T33: =IFERROR((Tabela1[[#This Row],[LITROS CONSUMIDOS]]*$U$1)/Tabela1[[#This Row],[HODÔMETRO]],"-") -> 3.2096181
A34: VOLVO/FH 500 6X4T S BIO | B34: 2025 | C34: TAW8C01 | D34: VIBRA | E34: =IFERROR(_xlfn.XLOOKUP(Tabela1[[#This Row],[PLACA]],'Telemetria Sighra'!F:F,'Telemetria Sighra'!T:T),"NÃO EMBARCADO") -> ROBERTO RIVELINO CABRAL - 234 | F34: {=SUMPRODUCT((ISNUMBER(FIND(C34,Faturamento!$F$2:$F$1014)))*(Faturamento!$AA$2:$AA$1014))} -> 1346 | G34: =Tabela1[[#This Row],[HODÔMETRO]]-Tabela1[[#This Row],[KM CARREGADO]] -> 849.84 | H34: =_xlfn.XLOOKUP(C34,'Telemetria Sighra'!F:F,'Telemetria Sighra'!R:R,0) -> 2195.84 | I34: =SUMIF(Faturamento!AC:AC,C34,Faturamento!T:T) -> 20291.69 | J34: {=SUMPRODUCT((ISNUMBER(FIND(C34,Faturamento!$F$2:$F$1014)))*(Faturamento!$R$2:$R$1014))} -> 247351 | K34: =$AH$2/30*$AA$1 -> 9479.7957 | L34: 4.4694 | M34: 69761 | N34: =Tabela1[[#This Row],[RESULTADO]]/Tabela1[[#This Row],[EBITDA ESTIMADO]] -> 0.014303221 | O34: =Tabela1[[#This Row],[FATURAMENTO]]-Tabela1[[#This Row],[CUSTO FIXO (SEM DEPREC.)]]-(Tabela1[[#This Row],[CUSTO VARIÁVEL]]*Tabela1[[#This Row],[HODÔMETRO]])+IF(COUNTIFS('ROTAS REALIZADAS'!A:A,Tabela1[[#This Row],[PLACA]],'ROTAS REALIZADAS'!A:A,"SANTOS/PAULINIA")>0,$AA$1*1233.33,0) -> 997.80698 | P34: =IFERROR(Tabela1[[#This Row],[RESULTADO]]/Tabela1[[#This Row],[FATURAMENTO]],"-") -> 0.049173183 | Q34: =IFERROR(I34/H34,"-") -> 9.2409693 | R34: =_xlfn.XLOOKUP(C34,'Telemetria Sighra'!F:F,'Telemetria Sighra'!S:S,0) -> 1.8177898 | S34: =_xlfn.XLOOKUP(Tabela1[[#This Row],[PLACA]],'Telemetria Sighra'!F:F,'Telemetria Sighra'!I:I,0) -> 1208.11 | T34: =IFERROR((Tabela1[[#This Row],[LITROS CONSUMIDOS]]*$U$1)/Tabela1[[#This Row],[HODÔMETRO]],"-") -> 3.3010875
A35: VOLVO/FH 500 6X4T S BIO | B35: 2025 | C35: TAW2A65 | D35: VIBRA | E35: =IFERROR(_xlfn.XLOOKUP(Tabela1[[#This Row],[PLACA]],'Telemetria Sighra'!F:F,'Telemetria Sighra'!T:T),"NÃO EMBARCADO") -> JOSE ARIMATEIA DA SILVA - 63 | F35: {=SUMPRODUCT((ISNUMBER(FIND(C35,Faturamento!$F$2:$F$1014)))*(Faturamento!$AA$2:$AA$1014))} -> 856 | G35: =Tabela1[[#This Row],[HODÔMETRO]]-Tabela1[[#This Row],[KM CARREGADO]] -> 65.51 | H35: =_xlfn.XLOOKUP(C35,'Telemetria Sighra'!F:F,'Telemetria Sighra'!R:R,0) -> 921.51 | I35: =SUMIF(Faturamento!AC:AC,C35,Faturamento!T:T) -> 14702.75 | J35: {=SUMPRODUCT((ISNUMBER(FIND(C35,Faturamento!$F$2:$F$1014)))*(Faturamento!$R$2:$R$1014))} -> 116817 | K35: =$AH$2/30*$AA$1 -> 9479.7957 | L35: 4.4694 | M35: 69761 | N35: =Tabela1[[#This Row],[RESULTADO]]/Tabela1[[#This Row],[EBITDA ESTIMADO]] -> 0.015830586 | O35: =Tabela1[[#This Row],[FATURAMENTO]]-Tabela1[[#This Row],[CUSTO FIXO (SEM DEPREC.)]]-(Tabela1[[#This Row],[CUSTO VARIÁVEL]]*Tabela1[[#This Row],[HODÔMETRO]])+IF(COUNTIFS('ROTAS REALIZADAS'!A:A,Tabela1[[#This Row],[PLACA]],'ROTAS REALIZADAS'!A:A,"SANTOS/PAULINIA")>0,$AA$1*1233.33,0) -> 1104.3575 | P35: =IFERROR(Tabela1[[#This Row],[RESULTADO]]/Tabela1[[#This Row],[FATURAMENTO]],"-") -> 0.075112308 | Q35: =IFERROR(I35/H35,"-") -> 15.955063 | R35: =_xlfn.XLOOKUP(C35,'Telemetria Sighra'!F:F,'Telemetria Sighra'!S:S,0) -> 1.8194255 | S35: =_xlfn.XLOOKUP(Tabela1[[#This Row],[PLACA]],'Telemetria Sighra'!F:F,'Telemetria Sighra'!I:I,0) -> 506.55 | T35: =IFERROR((Tabela1[[#This Row],[LITROS CONSUMIDOS]]*$U$1)/Tabela1[[#This Row],[HODÔMETRO]],"-") -> 3.2981736
A36: DAF/XF FTT 530 | B36: 2023 | C36: SEE0I05 | D36: CAMERA | E36: =IFERROR(_xlfn.XLOOKUP(Tabela1[[#This Row],[PLACA]],'Telemetria Sighra'!F:F,'Telemetria Sighra'!T:T),"NÃO EMBARCADO") -> RODRIGO DOS SANTOS ALVES - 250 | F36: {=SUMPRODUCT((ISNUMBER(FIND(C36,Faturamento!$F$2:$F$1014)))*(Faturamento!$AA$2:$AA$1014))} -> 1071 | G36: =Tabela1[[#This Row],[HODÔMETRO]]-Tabela1[[#This Row],[KM CARREGADO]] -> 940.69 | H36: =_xlfn.XLOOKUP(C36,'Telemetria Sighra'!F:F,'Telemetria Sighra'!R:R,0) -> 2011.69 | I36: =SUMIF(Faturamento!AC:AC,C36,Faturamento!T:T) -> 19742.8 | J36: {=SUMPRODUCT((ISNUMBER(FIND(C36,Faturamento!$F$2:$F$1014)))*(Faturamento!$R$2:$R$1014))} -> 177211 | K36: =$AH$2/30*$AA$1 -> 9479.7957 | L36: 4.4694 | M36: 53428 | N36: =Tabela1[[#This Row],[RESULTADO]]/Tabela1[[#This Row],[EBITDA ESTIMADO]] -> 0.023806936 | O36: =Tabela1[[#This Row],[FATURAMENTO]]-Tabela1[[#This Row],[CUSTO FIXO (SEM DEPREC.)]]-(Tabela1[[#This Row],[CUSTO VARIÁVEL]]*Tabela1[[#This Row],[HODÔMETRO]])+IF(COUNTIFS('ROTAS REALIZADAS'!A:A,Tabela1[[#This Row],[PLACA]],'ROTAS REALIZADAS'!A:A,"SANTOS/PAULINIA")>0,$AA$1*1233.33,0) -> 1271.957 | P36: =IFERROR(Tabela1[[#This Row],[RESULTADO]]/Tabela1[[#This Row],[FATURAMENTO]],"-") -> 0.064426373 | Q36: =IFERROR(I36/H36,"-") -> 9.814037 | R36: =_xlfn.XLOOKUP(C36,'Telemetria Sighra'!F:F,'Telemetria Sighra'!S:S,0) -> 1.8929556 | S36: =_xlfn.XLOOKUP(Tabela1[[#This Row],[PLACA]],'Telemetria Sighra'!F:F,'Telemetria Sighra'!I:I,0) -> 1062.83 | T36: =IFERROR((Tabela1[[#This Row],[LITROS CONSUMIDOS]]*$U$1)/Tabela1[[#This Row],[HODÔMETRO]],"-") -> 3.1699616
A37: VOLVO/FH 500 6X4T S BIO | B37: 2025 | C37: TAW8C09 | D37: ARAUCARIA X CASCAVEL | E37: =IFERROR(_xlfn.XLOOKUP(Tabela1[[#This Row],[PLACA]],'Telemetria Sighra'!F:F,'Telemetria Sighra'!T:T),"NÃO EMBARCADO") -> CLAIR SONAI - 67 | F37: {=SUMPRODUCT((ISNUMBER(FIND(C37,Faturamento!$F$2:$F$1014)))*(Faturamento!$AA$2:$AA$1014))} -> 1286 | G37: =Tabela1[[#This Row],[HODÔMETRO]]-Tabela1[[#This Row],[KM CARREGADO]] -> 998.22 | H37: =_xlfn.XLOOKUP(C37,'Telemetria Sighra'!F:F,'Telemetria Sighra'!R:R,0) -> 2284.22 | I37: =SUMIF(Faturamento!AC:AC,C37,Faturamento!T:T) -> 22714.9 | J37: {=SUMPRODUCT((ISNUMBER(FIND(C37,Faturamento!$F$2:$F$1014)))*(Faturamento!$R$2:$R$1014))} -> 239819 | K37: =$AH$2/30*$AA$1 -> 9479.7957 | L37: 4.4694 | M37: 34268 | N37: =Tabela1[[#This Row],[RESULTADO]]/Tabela1[[#This Row],[EBITDA ESTIMADO]] -> 0.08830429 | O37: =Tabela1[[#This Row],[FATURAMENTO]]-Tabela1[[#This Row],[CUSTO FIXO (SEM DEPREC.)]]-(Tabela1[[#This Row],[CUSTO VARIÁVEL]]*Tabela1[[#This Row],[HODÔMETRO]])+IF(COUNTIFS('ROTAS REALIZADAS'!A:A,Tabela1[[#This Row],[PLACA]],'ROTAS REALIZADAS'!A:A,"SANTOS/PAULINIA")>0,$AA$1*1233.33,0) -> 3026.0114 | P37: =IFERROR(Tabela1[[#This Row],[RESULTADO]]/Tabela1[[#This Row],[FATURAMENTO]],"-") -> 0.13321703 | Q37: =IFERROR(I37/H37,"-") -> 9.9442698 | R37: =_xlfn.XLOOKUP(C37,'Telemetria Sighra'!F:F,'Telemetria Sighra'!S:S,0) -> 1.85428 | S37: =_xlfn.XLOOKUP(Tabela1[[#This Row],[PLACA]],'Telemetria Sighra'!F:F,'Telemetria Sighra'!I:I,0) -> 1232.02 | T37: =IFERROR((Tabela1[[#This Row],[LITROS CONSUMIDOS]]*$U$1)/Tabela1[[#This Row],[HODÔMETRO]],"-") -> 3.2361681
A38: DAF/XF FTT 530 | B38: 2021 | C38: RHH5C92 | D38: SANTOS X PAULINIA | E38: =IFERROR(_xlfn.XLOOKUP(Tabela1[[#This Row],[PLACA]],'Telemetria Sighra'!F:F,'Telemetria Sighra'!T:T),"NÃO EMBARCADO") -> CLAUDEMIR SOARES - 252 | F38: {=SUMPRODUCT((ISNUMBER(FIND(C38,Faturamento!$F$2:$F$1014)))*(Faturamento!$AA$2:$AA$1014))} -> 1727 | G38: =Tabela1[[#This Row],[HODÔMETRO]]-Tabela1[[#This Row],[KM CARREGADO]] -> 554.52 | H38: =_xlfn.XLOOKUP(C38,'Telemetria Sighra'!F:F,'Telemetria Sighra'!R:R,0) -> 2281.52 | I38: =SUMIF(Faturamento!AC:AC,C38,Faturamento!T:T) -> 23075.99 | J38: {=SUMPRODUCT((ISNUMBER(FIND(C38,Faturamento!$F$2:$F$1014)))*(Faturamento!$R$2:$R$1014))} -> 117433 | K38: =$AH$2/30*$AA$1 -> 9479.7957 | L38: 4.4694 | M38: 39990 | N38: =Tabela1[[#This Row],[RESULTADO]]/Tabela1[[#This Row],[EBITDA ESTIMADO]] -> 0.08500047 | O38: =Tabela1[[#This Row],[FATURAMENTO]]-Tabela1[[#This Row],[CUSTO FIXO (SEM DEPREC.)]]-(Tabela1[[#This Row],[CUSTO VARIÁVEL]]*Tabela1[[#This Row],[HODÔMETRO]])+IF(COUNTIFS('ROTAS REALIZADAS'!A:A,Tabela1[[#This Row],[PLACA]],'ROTAS REALIZADAS'!A:A,"SANTOS/PAULINIA")>0,$AA$1*1233.33,0) -> 3399.1688 | P38: =IFERROR(Tabela1[[#This Row],[RESULTADO]]/Tabela1[[#This Row],[FATURAMENTO]],"-") -> 0.14730327 | Q38: =IFERROR(I38/H38,"-") -> 10.114305 | R38: =_xlfn.XLOOKUP(C38,'Telemetria Sighra'!F:F,'Telemetria Sighra'!S:S,0) -> 1.5780198 | S38: =_xlfn.XLOOKUP(Tabela1[[#This Row],[PLACA]],'Telemetria Sighra'!F:F,'Telemetria Sighra'!I:I,0) -> 1445.85 | T38: =IFERROR((Tabela1[[#This Row],[LITROS CONSUMIDOS]]*$U$1)/Tabela1[[#This Row],[HODÔMETRO]],"-") -> 3.8023335
A39: SCANIA/R 480 A6X4 | B39: 2017 | C39: BBM8G62 | D39: METANOL | E39: =IFERROR(_xlfn.XLOOKUP(Tabela1[[#This Row],[PLACA]],'Telemetria Sighra'!F:F,'Telemetria Sighra'!T:T),"NÃO EMBARCADO") -> LUIZ GERVASIO STROPARO - 10759 | F39: {=SUMPRODUCT((ISNUMBER(FIND(C39,Faturamento!$F$2:$F$1014)))*(Faturamento!$AA$2:$AA$1014))} -> 660 | G39: =Tabela1[[#This Row],[HODÔMETRO]]-Tabela1[[#This Row],[KM CARREGADO]] -> 537.52 | H39: =_xlfn.XLOOKUP(C39,'Telemetria Sighra'!F:F,'Telemetria Sighra'!R:R,0) -> 1197.52 | I39: =SUMIF(Faturamento!AC:AC,C39,Faturamento!T:T) -> 17105.81 | J39: {=SUMPRODUCT((ISNUMBER(FIND(C39,Faturamento!$F$2:$F$1014)))*(Faturamento!$R$2:$R$1014))} -> 112240 | K39: =$AD$2/30*$AA$1 -> 7856.0195 | L39: 3.55 | M39: 47896 | N39: =Tabela1[[#This Row],[RESULTADO]]/Tabela1[[#This Row],[EBITDA ESTIMADO]] -> 0.10436351 | O39: =Tabela1[[#This Row],[FATURAMENTO]]-Tabela1[[#This Row],[CUSTO FIXO (SEM DEPREC.)]]-(Tabela1[[#This Row],[CUSTO VARIÁVEL]]*Tabela1[[#This Row],[HODÔMETRO]])+IF(COUNTIFS('ROTAS REALIZADAS'!A:A,Tabela1[[#This Row],[PLACA]],'ROTAS REALIZADAS'!A:A,"SANTOS/PAULINIA")>0,$AA$1*1233.33,0) -> 4998.5945 | P39: =IFERROR(Tabela1[[#This Row],[RESULTADO]]/Tabela1[[#This Row],[FATURAMENTO]],"-") -> 0.29221618 | Q39: =IFERROR(I39/H39,"-") -> 14.284363 | R39: =_xlfn.XLOOKUP(C39,'Telemetria Sighra'!F:F,'Telemetria Sighra'!S:S,0) -> 1.55823 | S39: =_xlfn.XLOOKUP(Tabela1[[#This Row],[PLACA]],'Telemetria Sighra'!F:F,'Telemetria Sighra'!I:I,0) -> 768.59 | T39: =IFERROR((Tabela1[[#This Row],[LITROS CONSUMIDOS]]*$U$1)/Tabela1[[#This Row],[HODÔMETRO]],"-") -> 3.8509085
A40: SCANIA/R 480 A6X4 | B40: 2017 | C40: BBL9D24 | D40: METANOL | E40: =IFERROR(_xlfn.XLOOKUP(Tabela1[[#This Row],[PLACA]],'Telemetria Sighra'!F:F,'Telemetria Sighra'!T:T),"NÃO EMBARCADO") -> ANTONIO MARCOS GONCALVES - 90 | F40: {=SUMPRODUCT((ISNUMBER(FIND(C40,Faturamento!$F$2:$F$1014)))*(Faturamento!$AA$2:$AA$1014))} -> 1412 | G40: =Tabela1[[#This Row],[HODÔMETRO]]-Tabela1[[#This Row],[KM CARREGADO]] -> 871.68 | H40: =_xlfn.XLOOKUP(C40,'Telemetria Sighra'!F:F,'Telemetria Sighra'!R:R,0) -> 2283.68 | I40: =SUMIF(Faturamento!AC:AC,C40,Faturamento!T:T) -> 20994.5 | J40: {=SUMPRODUCT((ISNUMBER(FIND(C40,Faturamento!$F$2:$F$1014)))*(Faturamento!$R$2:$R$1014))} -> 165378 | K40: =$AD$2/30*$AA$1 -> 7856.0195 | L40: 3.55 | M40: 47896 | N40: =Tabela1[[#This Row],[RESULTADO]]/Tabela1[[#This Row],[EBITDA ESTIMADO]] -> 0.10504878 | O40: =Tabela1[[#This Row],[FATURAMENTO]]-Tabela1[[#This Row],[CUSTO FIXO (SEM DEPREC.)]]-(Tabela1[[#This Row],[CUSTO VARIÁVEL]]*Tabela1[[#This Row],[HODÔMETRO]])+IF(COUNTIFS('ROTAS REALIZADAS'!A:A,Tabela1[[#This Row],[PLACA]],'ROTAS REALIZADAS'!A:A,"SANTOS/PAULINIA")>0,$AA$1*1233.33,0) -> 5031.4165 | P40: =IFERROR(Tabela1[[#This Row],[RESULTADO]]/Tabela1[[#This Row],[FATURAMENTO]],"-") -> 0.23965403 | Q40: =IFERROR(I40/H40,"-") -> 9.1932758 | R40: =_xlfn.XLOOKUP(C40,'Telemetria Sighra'!F:F,'Telemetria Sighra'!S:S,0) -> 2.0101474 | S40: =_xlfn.XLOOKUP(Tabela1[[#This Row],[PLACA]],'Telemetria Sighra'!F:F,'Telemetria Sighra'!I:I,0) -> 1136.25 | T40: =IFERROR((Tabela1[[#This Row],[LITROS CONSUMIDOS]]*$U$1)/Tabela1[[#This Row],[HODÔMETRO]],"-") -> 2.9853132
A41: DAF/XF FTT 530 | B41: 2021 | C41: RHH5C95 | D41: SANTOS X PAULINIA | E41: =IFERROR(_xlfn.XLOOKUP(Tabela1[[#This Row],[PLACA]],'Telemetria Sighra'!F:F,'Telemetria Sighra'!T:T),"NÃO EMBARCADO") -> REINALDO FERNEDA - 249 | F41: {=SUMPRODUCT((ISNUMBER(FIND(C41,Faturamento!$F$2:$F$1014)))*(Faturamento!$AA$2:$AA$1014))} -> 1443 | G41: =Tabela1[[#This Row],[HODÔMETRO]]-Tabela1[[#This Row],[KM CARREGADO]] -> 1286.03 | H41: =_xlfn.XLOOKUP(C41,'Telemetria Sighra'!F:F,'Telemetria Sighra'!R:R,0) -> 2729.03 | I41: =SUMIF(Faturamento!AC:AC,C41,Faturamento!T:T) -> 28435.69 | J41: {=SUMPRODUCT((ISNUMBER(FIND(C41,Faturamento!$F$2:$F$1014)))*(Faturamento!$R$2:$R$1014))} -> 117175 | K41: =$AH$2/30*$AA$1 -> 9479.7957 | L41: 4.4694 | M41: 39990 | N41: =Tabela1[[#This Row],[RESULTADO]]/Tabela1[[#This Row],[EBITDA ESTIMADO]] -> 0.16901144 | O41: =Tabela1[[#This Row],[FATURAMENTO]]-Tabela1[[#This Row],[CUSTO FIXO (SEM DEPREC.)]]-(Tabela1[[#This Row],[CUSTO VARIÁVEL]]*Tabela1[[#This Row],[HODÔMETRO]])+IF(COUNTIFS('ROTAS REALIZADAS'!A:A,Tabela1[[#This Row],[PLACA]],'ROTAS REALIZADAS'!A:A,"SANTOS/PAULINIA")>0,$AA$1*1233.33,0) -> 6758.7676 | P41: =IFERROR(Tabela1[[#This Row],[RESULTADO]]/Tabela1[[#This Row],[FATURAMENTO]],"-") -> 0.23768608 | Q41: =IFERROR(I41/H41,"-") -> 10.419706 | R41: =_xlfn.XLOOKUP(C41,'Telemetria Sighra'!F:F,'Telemetria Sighra'!S:S,0) -> 1.6615204 | S41: =_xlfn.XLOOKUP(Tabela1[[#This Row],[PLACA]],'Telemetria Sighra'!F:F,'Telemetria Sighra'!I:I,0) -> 1642.61 | T41: =IFERROR((Tabela1[[#This Row],[LITROS CONSUMIDOS]]*$U$1)/Tabela1[[#This Row],[HODÔMETRO]],"-") -> 3.611415
A42: VOLVO/FH 540 6X4T | B42: 2020 | C42: BDQ4E53 | D42: ARAUCARIA X CASCAVEL | E42: =IFERROR(_xlfn.XLOOKUP(Tabela1[[#This Row],[PLACA]],'Telemetria Sighra'!F:F,'Telemetria Sighra'!T:T),"NÃO EMBARCADO") -> JOAO GABRIEL DA CRUZ - 10724 | F42: {=SUMPRODUCT((ISNUMBER(FIND(C42,Faturamento!$F$2:$F$1014)))*(Faturamento!$AA$2:$AA$1014))} -> 1583 | G42: =Tabela1[[#This Row],[HODÔMETRO]]-Tabela1[[#This Row],[KM CARREGADO]] -> 300.7 | H42: =_xlfn.XLOOKUP(C42,'Telemetria Sighra'!F:F,'Telemetria Sighra'!R:R,0) -> 1883.7 | I42: =SUMIF(Faturamento!AC:AC,C42,Faturamento!T:T) -> 25279.56 | J42: {=SUMPRODUCT((ISNUMBER(FIND(C42,Faturamento!$F$2:$F$1014)))*(Faturamento!$R$2:$R$1014))} -> 104635 | K42: =$AH$2/30*$AA$1 -> 9479.7957 | L42: 4.4694 | M42: 34268 | N42: =Tabela1[[#This Row],[RESULTADO]]/Tabela1[[#This Row],[EBITDA ESTIMADO]] -> 0.21538332 | O42: =Tabela1[[#This Row],[FATURAMENTO]]-Tabela1[[#This Row],[CUSTO FIXO (SEM DEPREC.)]]-(Tabela1[[#This Row],[CUSTO VARIÁVEL]]*Tabela1[[#This Row],[HODÔMETRO]])+IF(COUNTIFS('ROTAS REALIZADAS'!A:A,Tabela1[[#This Row],[PLACA]],'ROTAS REALIZADAS'!A:A,"SANTOS/PAULINIA")>0,$AA$1*1233.33,0) -> 7380.7555 | P42: =IFERROR(Tabela1[[#This Row],[RESULTADO]]/Tabela1[[#This Row],[FATURAMENTO]],"-") -> 0.29196535 | Q42: =IFERROR(I42/H42,"-") -> 13.420162 | R42: =_xlfn.XLOOKUP(C42,'Telemetria Sighra'!F:F,'Telemetria Sighra'!S:S,0) -> 1.3760546 | S42: =_xlfn.XLOOKUP(Tabela1[[#This Row],[PLACA]],'Telemetria Sighra'!F:F,'Telemetria Sighra'!I:I,0) -> 1369.03 | T42: =IFERROR((Tabela1[[#This Row],[LITROS CONSUMIDOS]]*$U$1)/Tabela1[[#This Row],[HODÔMETRO]],"-") -> 4.3606625
